Workbook

Sheet 파워링크_Summary
B2: 네이버 파워링크
B4: 구분 (1/1~1/31) | C4: 노출 | D4: 클릭 | E4: 광고비 (vat 포함) | F4: 전환수
B5: 누적 달성량 | C5: =C68 -> 16756 | D5: =D68 -> 451 | E5: =G68 -> 2896949 | F5: =H68 -> 94
B7: ▶ 성과 추이 | L7: ▶ 코멘트
L9: 3월 1주차 데이터 CTR 3.44% / CPC 6,047원 / 전환 수 29건 / 전환율 23.58% ㄴ 지난 2월 3주차 클릭 수 77건까지 감소, CTR 2.32% 하락하며 저조한 유입 성과 기록했으나, 이번 3월 1주차 클릭 수 123건, CTR 3.44% 기록하며 성과 회복 ㄴ 평일, 주말 모두 클릭 및 전환 모두 증가했으며 특히 평일에 CTR 2.48% > 3.58%, CVR 18.09% > 24.55% 큰 폭 상승하며 고성과 기록 ㄴ '무선카드단말기' 키워드에서 가장 많은 전환 발생했으며 그 외 '카드단말기대여', '카드단말기신청', '카드단말기교체', '카드단말기구입' 등 '카드단말기+OO' 조합 키워드에서 전환 발생
B32: ▶ 주차별 Total 성과
B33: 주차 | C33: 노출수 | D33: 클릭수 | E33: CTR | F33: CPC | G33: 광고비 | H33: 매출
H34: 전환수 | I34: CVR | J34: 전환당 비용
B35: 1월 1주차 (1~4일) | C35: =SUM(C69:C72) -> 1947 | D35: =SUM(D69:D72) -> 54 | E35: =IFERROR(D35/C35,) -> 0.027734977 | F35: =IFERROR(G35/D35,0) -> 6459.8519 | G35: =SUM(G69:G72) -> 348832 | H35: =SUM(H69:H72) -> 11 | I35: =IFERROR(H35/D35,0) -> 0.2037037 | J35: =IFERROR(G35/H35,0) -> 31712
B36: 2/9 ~ 2/15 | C36: =SUM(C73:C79) -> 3644 | D36: =SUM(D73:D79) -> 94 | E36: =IFERROR(D36/C36,) -> 0.025795829 | F36: =IFERROR(G36/D36,0) -> 7004.3085 | G36: =SUM(G73:G79) -> 658405 | H36: =SUM(H73:H79) -> 16 | I36: =IFERROR(H36/D36,0) -> 0.17021277 | J36: =IFERROR(G36/H36,0) -> 41150.312
B37: 2/16 ~ 2/22 | C37: =SUM(C80:C86) -> 3324 | D37: =SUM(D80:D86) -> 77 | E37: =IFERROR(D37/C37,) -> 0.023164862 | F37: =IFERROR(G37/D37,0) -> 6209 | G37: =SUM(G80:G86) -> 478093 | H37: =SUM(H80:H86) -> 20 | I37: =IFERROR(H37/D37,0) -> 0.25974026 | J37: =IFERROR(G37/H37,0) -> 23904.65
B38: 2/23 ~ 3/1 | C38: =SUM(C87:C93) -> 4262 | D38: =SUM(D87:D93) -> 103 | E38: =IFERROR(D38/C38,) -> 0.024167058 | F38: =IFERROR(G38/D38,0) -> 6484.4466 | G38: =SUM(G87:G93) -> 667898 | H38: =SUM(H87:H93) -> 18 | I38: =IFERROR(H38/D38,0) -> 0.17475728 | J38: =IFERROR(G38/H38,0) -> 37105.444
B39: 3/2 ~ 3/8 | C39: =SUM(C94:C100) -> 3579 | D39: =SUM(D94:D100) -> 123 | E39: =IFERROR(D39/C39,) -> 0.034367142 | F39: =IFERROR(G39/D39,0) -> 6046.5122 | G39: =SUM(G94:G100) -> 743721 | H39: =SUM(H94:H100) -> 29 | I39: =IFERROR(H39/D39,0) -> 0.23577236 | J39: =IFERROR(G39/H39,0) -> 25645.552
B40: 전주대비 | C40: =IFERROR(C39/C38-1,"-") -> -0.1602534 | D40: =IFERROR(D39/D38-1,"-") -> 0.19417476 | E40: =IFERROR(E39/E38-1,"-") -> 0.42206561 | F40: =IFERROR(F39/F38-1,"-") -> -0.067536127 | G40: =IFERROR(G39/G38-1,"-") -> 0.11352482 | H40: =IFERROR(H39/H38-1,"-") -> 0.61111111 | I40: =IFERROR(I39/I38-1,"-") -> 0.34914182 | J40: =IFERROR(J39/J38-1,"-") -> -0.30884666
B43: ▶ 주차별 평일 성과
B44: 주차 | C44: 노출수 | D44: 클릭수 | E44: CTR | F44: CPC | G44: 광고비 | H44: 매출
H45: 전환수 | I45: CVR | J45: 전환당 비용
B46: 1월 1주차 (1~2일) | C46: =SUM(C69:C70) -> 1292 | D46: =SUM(D69:D70) -> 40 | E46: =IFERROR(D46/C46,) -> 0.030959752 | F46: =IFERROR(G46/D46,0) -> 7267.7 | G46: =SUM(G69:G70) -> 290708 | H46: =SUM(H69:H70) -> 9 | I46: =IFERROR(H46/D46,0) -> 0.225 | J46: =IFERROR(G46/H46,0) -> 32300.889
B47: 2/9 ~ 2/13 | C47: =SUM(C73:C77) -> 3087 | D47: =SUM(D73:D77) -> 83 | E47: =IFERROR(D47/C47,) -> 0.026886945 | F47: =IFERROR(G47/D47,0) -> 7300.8193 | G47: =SUM(G73:G77) -> 605968 | H47: =SUM(H73:H77) -> 15 | I47: =IFERROR(H47/D47,0) -> 0.18072289 | J47: =IFERROR(G47/H47,0) -> 40397.867
B48: 2/16 ~ 2/22 | C48: =SUM(C80:C84) -> 2650 | D48: =SUM(D80:D84) -> 67 | E48: =IFERROR(D48/C48,) -> 0.025283019 | F48: =IFERROR(G48/D48,0) -> 6388.209 | G48: =SUM(G80:G84) -> 428010 | H48: =SUM(H80:H84) -> 14 | I48: =IFERROR(H48/D48,0) -> 0.20895522 | J48: =IFERROR(G48/H48,0) -> 30572.143
B49: 2/23 ~ 2/27 | C49: =SUM(C87:C91) -> 3790 | D49: =SUM(D87:D91) -> 94 | E49: =IFERROR(D49/C49,) -> 0.024802111 | F49: =IFERROR(G49/D49,0) -> 6777.1702 | G49: =SUM(G87:G91) -> 637054 | H49: =SUM(H87:H91) -> 17 | I49: =IFERROR(H49/D49,0) -> 0.18085106 | J49: =IFERROR(G49/H49,0) -> 37473.765
B50: 3/2 ~ 3/6 | C50: =SUM(C94:C98) -> 3074 | D50: =SUM(D94:D98) -> 110 | E50: =IFERROR(D50/C50,) -> 0.035783995 | F50: =IFERROR(G50/D50,0) -> 6372.3 | G50: =SUM(G94:G98) -> 700953 | H50: =SUM(H94:H98) -> 27 | I50: =IFERROR(H50/D50,0) -> 0.24545455 | J50: =IFERROR(G50/H50,0) -> 25961.222
B51: 전주대비 | C51: =IFERROR(C50/C49-1,"-") -> -0.18891821 | D51: =IFERROR(D50/D49-1,"-") -> 0.17021277 | E51: =IFERROR(E50/E49-1,"-") -> 0.44278022 | F51: =IFERROR(F50/F49-1,"-") -> -0.059740305 | G51: =IFERROR(G50/G49-1,"-") -> 0.1003039 | H51: =IFERROR(H50/H49-1,"-") -> 0.58823529 | I51: =IFERROR(I50/I49-1,"-") -> 0.35721925 | J51: =IFERROR(J50/J49-1,"-") -> -0.30721606
B54: ▶ 주차별 주말 성과
B55: 주차 | C55: 노출수 | D55: 클릭수 | E55: CTR | F55: CPC | G55: 광고비 | H55: 매출
H56: 전환수 | I56: CVR | J56: 전환당 비용
B57: 1월 1주차 (3~4일) | C57: =SUM(C71:C72) -> 655 | D57: =SUM(D71:D72) -> 14 | E57: =IFERROR(D57/C57,) -> 0.021374046 | F57: =IFERROR(G57/D57,0) -> 4151.7143 | G57: =SUM(G71:G72) -> 58124 | H57: =SUM(H71:H72) -> 2 | I57: =IFERROR(H57/D57,0) -> 0.14285714 | J57: =IFERROR(G57/H57,0) -> 29062
B58: 2/14 ~ 2/15 | C58: =SUM(C78:C79) -> 557 | D58: =SUM(D78:D79) -> 11 | E58: =IFERROR(D58/C58,) -> 0.019748654 | F58: =IFERROR(G58/D58,0) -> 4767 | G58: =SUM(G78:G79) -> 52437 | H58: =SUM(H78:H79) -> 1 | I58: =IFERROR(H58/D58,0) -> 0.090909091 | J58: =IFERROR(G58/H58,0) -> 52437
B59: 2/21 ~ 2/22 | C59: =SUM(C85:C86) -> 674 | D59: =SUM(D85:D86) -> 10 | E59: =IFERROR(D59/C59,) -> 0.014836795 | F59: =IFERROR(G59/D59,0) -> 5008.3 | G59: =SUM(G85:G86) -> 50083 | H59: =SUM(H85:H86) -> 6 | I59: =IFERROR(H59/D59,0) -> 0.6 | J59: =IFERROR(G59/H59,0) -> 8347.1667
B60: 2/28 ~ 3/1 | C60: =SUM(C92:C93) -> 472 | D60: =SUM(D92:D93) -> 9 | E60: =IFERROR(D60/C60,) -> 0.019067797 | F60: =IFERROR(G60/D60,0) -> 3427.1111 | G60: =SUM(G92:G93) -> 30844 | H60: =SUM(H92:H93) -> 1 | I60: =IFERROR(H60/D60,0) -> 0.11111111 | J60: =IFERROR(G60/H60,0) -> 30844
B61: 3/7 ~ 3/8 | C61: =SUM(C99:C100) -> 505 | D61: =SUM(D99:D100) -> 13 | E61: =IFERROR(D61/C61,) -> 0.025742574 | F61: =IFERROR(G61/D61,0) -> 3289.8462 | G61: =SUM(G99:G100) -> 42768 | H61: =SUM(H99:H100) -> 2 | I61: =IFERROR(H61/D61,0) -> 0.15384615 | J61: =IFERROR(G61/H61,0) -> 21384
B62: 전주대비 | C62: =IFERROR(C61/C60-1,"-") -> 0.069915254 | D62: =IFERROR(D61/D60-1,"-") -> 0.44444444 | E62: =IFERROR(E61/E60-1,"-") -> 0.35005501 | F62: =IFERROR(F61/F60-1,"-") -> -0.040052672 | G62: =IFERROR(G61/G60-1,"-") -> 0.38659058 | H62: =IFERROR(H61/H60-1,"-") -> 1 | I62: =IFERROR(I61/I60-1,"-") -> 0.38461538 | J62: =IFERROR(J61/J60-1,"-") -> -0.30670471
B65: ▶ 일자별 Total 성과
B66: 일자 | C66: 노출수 | D66: 클릭수 | E66: CTR | F66: CPC | G66: 광고비 | H66: 매출
H67: 전환수 | I67: CVR | J67: 전환당 비용
B68: 합계 | C68: =SUM(C69:C100) -> 16756 | D68: =SUM(D69:D100) -> 451 | E68: =IFERROR(D68/C68,) -> 0.026915732 | F68: =IFERROR(G68/D68,0) -> 6423.3902 | G68: =SUM(G69:G100) -> 2896949 | H68: =SUM(H69:H100) -> 94 | I68: =IFERROR(H68/D68,0) -> 0.20842572 | J68: =IFERROR(G68/H68,0) -> 30818.606
B69: 2026.01.01. | C69: =SUMIFS('파워링크 RAW'!E:E,'파워링크 RAW'!$A:$A,파워링크_Summary!$B69,'파워링크 RAW'!$D:$D,"파워링크") -> 279 | D69: =SUMIFS('파워링크 RAW'!F:F,'파워링크 RAW'!$A:$A,파워링크_Summary!$B69,'파워링크 RAW'!$D:$D,"파워링크") -> 9 | E69: =IFERROR(D69/C69,) -> 0.032258065 | F69: =IFERROR(G69/D69,0) -> 6029.2222 | G69: =SUMIFS('파워링크 RAW'!G:G,'파워링크 RAW'!$A:$A,파워링크_Summary!$B69,'파워링크 RAW'!$D:$D,"파워링크") -> 54263 | H69: =SUMIFS('파워링크 RAW'!H:H,'파워링크 RAW'!$A:$A,파워링크_Summary!$B69,'파워링크 RAW'!$D:$D,"파워링크") -> 3 | I69: =IFERROR(H69/D69,0) -> 0.33333333 | J69: =IFERROR(G69/H69,0) -> 18087.667
B70: 2026.01.02. | C70: =SUMIFS('파워링크 RAW'!E:E,'파워링크 RAW'!$A:$A,파워링크_Summary!$B70,'파워링크 RAW'!$D:$D,"파워링크") -> 1013 | D70: =SUMIFS('파워링크 RAW'!F:F,'파워링크 RAW'!$A:$A,파워링크_Summary!$B70,'파워링크 RAW'!$D:$D,"파워링크") -> 31 | E70: =IFERROR(D70/C70,) -> 0.030602172 | F70: =IFERROR(G70/D70,0) -> 7627.2581 | G70: =SUMIFS('파워링크 RAW'!G:G,'파워링크 RAW'!$A:$A,파워링크_Summary!$B70,'파워링크 RAW'!$D:$D,"파워링크") -> 236445 | H70: =SUMIFS('파워링크 RAW'!H:H,'파워링크 RAW'!$A:$A,파워링크_Summary!$B70,'파워링크 RAW'!$D:$D,"파워링크") -> 6 | I70: =IFERROR(H70/D70,0) -> 0.19354839 | J70: =IFERROR(G70/H70,0) -> 39407.5
B71: 2026.01.03. | C71: =SUMIFS('파워링크 RAW'!E:E,'파워링크 RAW'!$A:$A,파워링크_Summary!$B71,'파워링크 RAW'!$D:$D,"파워링크") -> 337 | D71: =SUMIFS('파워링크 RAW'!F:F,'파워링크 RAW'!$A:$A,파워링크_Summary!$B71,'파워링크 RAW'!$D:$D,"파워링크") -> 7 | E71: =IFERROR(D71/C71,) -> 0.020771513 | F71: =IFERROR(G71/D71,0) -> 4345 | G71: =SUMIFS('파워링크 RAW'!G:G,'파워링크 RAW'!$A:$A,파워링크_Summary!$B71,'파워링크 RAW'!$D:$D,"파워링크") -> 30415 | H71: =SUMIFS('파워링크 RAW'!H:H,'파워링크 RAW'!$A:$A,파워링크_Summary!$B71,'파워링크 RAW'!$D:$D,"파워링크") -> 0 | I71: =IFERROR(H71/D71,0) -> 0 | J71: =IFERROR(G71/H71,0) -> 0
B72: 2026.01.04. | C72: =SUMIFS('파워링크 RAW'!E:E,'파워링크 RAW'!$A:$A,파워링크_Summary!$B72,'파워링크 RAW'!$D:$D,"파워링크") -> 318 | D72: =SUMIFS('파워링크 RAW'!F:F,'파워링크 RAW'!$A:$A,파워링크_Summary!$B72,'파워링크 RAW'!$D:$D,"파워링크") -> 7 | E72: =IFERROR(D72/C72,) -> 0.022012579 | F72: =IFERROR(G72/D72,0) -> 3958.4286 | G72: =SUMIFS('파워링크 RAW'!G:G,'파워링크 RAW'!$A:$A,파워링크_Summary!$B72,'파워링크 RAW'!$D:$D,"파워링크") -> 27709 | H72: =SUMIFS('파워링크 RAW'!H:H,'파워링크 RAW'!$A:$A,파워링크_Summary!$B72,'파워링크 RAW'!$D:$D,"파워링크") -> 2 | I72: =IFERROR(H72/D72,0) -> 0.28571429 | J72: =IFERROR(G72/H72,0) -> 13854.5
...

Sheet 파워링크_상세데이터
B2: 네이버 파워링크
B4: ▶ 기기 별 성과
B5: 캠페인 | D5: 노출수 | E5: 클릭수 | F5: CTR | G5: CPC | H5: 광고비 | I5: 매출
I6: 전환수 | J6: CVR | K6: 전환당 비용
B7: PC | D7: =SUMIFS('파워링크 RAW'!E:E,'파워링크 RAW'!$D:$D,"파워링크",'파워링크 RAW'!$B:$B,파워링크_상세데이터!$B7) -> 14861 | E7: =SUMIFS('파워링크 RAW'!F:F,'파워링크 RAW'!$D:$D,"파워링크",'파워링크 RAW'!$B:$B,파워링크_상세데이터!$B7) -> 285 | F7: =IFERROR(E7/D7,) -> 0.019177713 | G7: =IFERROR(H7/E7,0) -> 7177.3649 | H7: =SUMIFS('파워링크 RAW'!G:G,'파워링크 RAW'!$D:$D,"파워링크",'파워링크 RAW'!$B:$B,파워링크_상세데이터!$B7) -> 2045549 | I7: =SUMIFS('파워링크 RAW'!H:H,'파워링크 RAW'!$D:$D,"파워링크",'파워링크 RAW'!$B:$B,파워링크_상세데이터!$B7) -> 55 | J7: =IFERROR(I7/E7,0) -> 0.19298246 | K7: =IFERROR(H7/I7,0) -> 37191.8
B8: 모바일 | D8: =SUMIFS('파워링크 RAW'!E:E,'파워링크 RAW'!$D:$D,"파워링크",'파워링크 RAW'!$B:$B,파워링크_상세데이터!$B8) -> 29569 | E8: =SUMIFS('파워링크 RAW'!F:F,'파워링크 RAW'!$D:$D,"파워링크",'파워링크 RAW'!$B:$B,파워링크_상세데이터!$B8) -> 810 | F8: =IFERROR(E8/D8,) -> 0.027393554 | G8: =IFERROR(H8/E8,0) -> 7181.6827 | H8: =SUMIFS('파워링크 RAW'!G:G,'파워링크 RAW'!$D:$D,"파워링크",'파워링크 RAW'!$B:$B,파워링크_상세데이터!$B8) -> 5817163 | I8: =SUMIFS('파워링크 RAW'!H:H,'파워링크 RAW'!$D:$D,"파워링크",'파워링크 RAW'!$B:$B,파워링크_상세데이터!$B8) -> 162 | J8: =IFERROR(I8/E8,0) -> 0.2 | K8: =IFERROR(H8/I8,0) -> 35908.414
B9: TOTAL | D9: =SUM(D7:D8) -> 44430 | E9: =SUM(E7:E8) -> 1095 | F9: =IFERROR(E9/D9,) -> 0.02464551 | G9: =IFERROR(H9/E9,0) -> 7180.5589 | H9: =SUM(H7:H8) -> 7862712 | I9: =SUM(I7:I8) -> 217 | J9: =IFERROR(I9/E9,0) -> 0.19817352 | K9: =IFERROR(H9/I9,0) -> 36233.696
B11: ▶ 캠페인 별 성과
B12: 캠페인 | D12: 노출수 | E12: 클릭수 | F12: CTR | G12: CPC | H12: 광고비 | I12: 매출
I13: 전환수 | J13: CVR | K13: 전환당 비용
B14: $페이파란 메인 파워링크(검색지면) | D14: =SUMIF($B$23:$B$48,$B14,D$23:D$48) -> 1539 | E14: =SUMIF($B$23:$B$48,$B14,E$23:E$48) -> 61 | F14: =IFERROR(E14/D14,) -> 0.039636127 | G14: =IFERROR(H14/E14,0) -> 7498.9344 | H14: =SUMIF($B$23:$B$48,$B14,H$23:H$48) -> 457435 | I14: =SUMIF($B$23:$B$48,$B14,I$23:I$48) -> 19 | J14: =IFERROR(I14/E14,0) -> 0.31147541 | K14: =IFERROR(H14/I14,0) -> 24075.526
B15: 페이파란 메인 파워링크(콘텐츠지면) | D15: =SUMIFS('파워링크 RAW'!E:E,'파워링크 RAW'!$D:$D,"파워링크",'파워링크 RAW'!$C:$C,파워링크_상세데이터!$B15) -> 0 | E15: =SUMIFS('파워링크 RAW'!F:F,'파워링크 RAW'!$D:$D,"파워링크",'파워링크 RAW'!$C:$C,파워링크_상세데이터!$B15) -> 0 | F15: =IFERROR(E15/D15,) -> 0 | G15: =IFERROR(H15/E15,0) -> 0 | H15: =SUMIFS('파워링크 RAW'!I:I,'파워링크 RAW'!$D:$D,"파워링크",'파워링크 RAW'!$C:$C,파워링크_상세데이터!$B15) -> 0 | I15: =SUMIFS('파워링크 RAW'!J:J,'파워링크 RAW'!$D:$D,"파워링크",'파워링크 RAW'!$C:$C,파워링크_상세데이터!$B15) -> 0 | J15: =IFERROR(I15/E15,0) -> 0 | K15: =IFERROR(H15/I15,0) -> 0
B16: $페이파란 서브 파워링크(검색지면) | D16: =SUMIF($B$23:$B$48,$B16,D$23:D$48) -> 2040 | E16: =SUMIF($B$23:$B$48,$B16,E$23:E$48) -> 62 | F16: =IFERROR(E16/D16,) -> 0.030392157 | G16: =IFERROR(H16/E16,0) -> 4617.5161 | H16: =SUMIF($B$23:$B$48,$B16,H$23:H$48) -> 286286 | I16: =SUMIF($B$23:$B$48,$B16,I$23:I$48) -> 10 | J16: =IFERROR(I16/E16,0) -> 0.16129032 | K16: =IFERROR(H16/I16,0) -> 28628.6
B17: 페이파란 서브 파워링크(콘텐츠지면) | D17: =SUMIFS('파워링크 RAW'!E:E,'파워링크 RAW'!$D:$D,"파워링크",'파워링크 RAW'!$C:$C,파워링크_상세데이터!$B17) -> 0 | E17: =SUMIFS('파워링크 RAW'!F:F,'파워링크 RAW'!$D:$D,"파워링크",'파워링크 RAW'!$C:$C,파워링크_상세데이터!$B17) -> 0 | F17: =IFERROR(E17/D17,) -> 0 | G17: =IFERROR(H17/E17,0) -> 0 | H17: =SUMIFS('파워링크 RAW'!G:G,'파워링크 RAW'!$D:$D,"파워링크",'파워링크 RAW'!$C:$C,파워링크_상세데이터!$B17) -> 0 | I17: =SUMIFS('파워링크 RAW'!H:H,'파워링크 RAW'!$D:$D,"파워링크",'파워링크 RAW'!$C:$C,파워링크_상세데이터!$B17) -> 0 | J17: =IFERROR(I17/E17,0) -> 0 | K17: =IFERROR(H17/I17,0) -> 0
B18: TOTAL | D18: =SUM(D14:D17) -> 3579 | E18: =SUM(E14:E17) -> 123 | F18: =IFERROR(E18/D18,) -> 0.034367142 | G18: =IFERROR(H18/E18,0) -> 6046.5122 | H18: =SUM(H14:H17) -> 743721 | I18: =SUM(I14:I17) -> 29 | J18: =IFERROR(I18/E18,0) -> 0.23577236 | K18: =IFERROR(H18/I18,0) -> 25645.552
B20: ▶ 그룹 별 성과 | K20: * 광고비 내림차순
B21: 캠페인 | C21: 그룹 | D21: 노출수 | E21: 클릭수 | F21: CTR | G21: CPC | H21: 광고비 | I21: 매출
I22: 전환수 | J22: CVR | K22: 전환당 비용
B23: $페이파란 서브 파워링크(검색지면) | C23: $단말기 MO | D23: 990 | E23: 33 | F23: =IFERROR(E23/D23,) -> 0.033333333 | G23: =IFERROR(H23/E23,0) -> 5630.6667 | H23: 185812 | I23: 4 | J23: =IFERROR(I23/E23,0) -> 0.12121212 | K23: =IFERROR(H23/I23,0) -> 46453
B24: $페이파란 메인 파워링크(검색지면) | C24: $비사업자MO (주간) | D24: 344 | E24: 11 | F24: =IFERROR(E24/D24,) -> 0.031976744 | G24: =IFERROR(H24/E24,0) -> 14353 | H24: 157883 | I24: 2 | J24: =IFERROR(I24/E24,0) -> 0.18181818 | K24: =IFERROR(H24/I24,0) -> 78941.5
B25: $페이파란 메인 파워링크(검색지면) | C25: $단말기MO (주간) | D25: 310 | E25: 19 | F25: =IFERROR(E25/D25,) -> 0.061290323 | G25: =IFERROR(H25/E25,0) -> 8110.4737 | H25: 154099 | I25: 9 | J25: =IFERROR(I25/E25,0) -> 0.47368421 | K25: =IFERROR(H25/I25,0) -> 17122.111
B26: $페이파란 서브 파워링크(검색지면) | C26: $단말기 PC | D26: 312 | E26: 13 | F26: =IFERROR(E26/D26,) -> 0.041666667 | G26: =IFERROR(H26/E26,0) -> 5754.6923 | H26: 74811 | I26: 2 | J26: =IFERROR(I26/E26,0) -> 0.15384615 | K26: =IFERROR(H26/I26,0) -> 37405.5
B27: $페이파란 메인 파워링크(검색지면) | C27: $단말기MO (야간) | D27: 207 | E27: 15 | F27: =IFERROR(E27/D27,) -> 0.072463768 | G27: =IFERROR(H27/E27,0) -> 3863.2 | H27: 57948 | I27: 1 | J27: =IFERROR(I27/E27,0) -> 0.066666667 | K27: =IFERROR(H27/I27,0) -> 57948
B28: $페이파란 메인 파워링크(검색지면) | C28: $단말기PC (주간) | D28: 258 | E28: 3 | F28: =IFERROR(E28/D28,) -> 0.011627907 | G28: =IFERROR(H28/E28,0) -> 8499.3333 | H28: 25498 | I28: 3 | J28: =IFERROR(I28/E28,0) -> 1 | K28: =IFERROR(H28/I28,0) -> 8499.3333
B29: $페이파란 메인 파워링크(검색지면) | C29: $단말기(주간)_다음 | D29: 28 | E29: 4 | F29: =IFERROR(E29/D29,) -> 0.14285714 | G29: =IFERROR(H29/E29,0) -> 4900.5 | H29: 19602 | I29: 1 | J29: =IFERROR(I29/E29,0) -> 0.25 | K29: =IFERROR(H29/I29,0) -> 19602
B30: $페이파란 메인 파워링크(검색지면) | C30: $비사업자MO (야간) | D30: 106 | E30: 3 | F30: =IFERROR(E30/D30,) -> 0.028301887 | G30: =IFERROR(H30/E30,0) -> 5650.3333 | H30: 16951 | I30: 1 | J30: =IFERROR(I30/E30,0) -> 0.33333333 | K30: =IFERROR(H30/I30,0) -> 16951
B31: $페이파란 메인 파워링크(검색지면) | C31: $단말기PC (야간) | D31: 53 | E31: 3 | F31: =IFERROR(E31/D31,) -> 0.056603774 | G31: =IFERROR(H31/E31,0) -> 4847.3333 | H31: 14542 | I31: 0 | J31: =IFERROR(I31/E31,0) -> 0 | K31: =IFERROR(H31/I31,0) -> 0
B32: $페이파란 서브 파워링크(검색지면) | C32: $*요식업종 MO | D32: 315 | E32: 3 | F32: =IFERROR(E32/D32,) -> 0.0095238095 | G32: =IFERROR(H32/E32,0) -> 3446.6667 | H32: 10340 | I32: 1 | J32: =IFERROR(I32/E32,0) -> 0.33333333 | K32: =IFERROR(H32/I32,0) -> 10340
B33: $페이파란 메인 파워링크(검색지면) | C33: $비사업자PC (주간) | D33: 176 | E33: 1 | F33: =IFERROR(E33/D33,) -> 0.0056818182 | G33: =IFERROR(H33/E33,0) -> 7876 | H33: 7876 | I33: 0 | J33: =IFERROR(I33/E33,0) -> 0 | K33: =IFERROR(H33/I33,0) -> 0
B34: $페이파란 서브 파워링크(검색지면) | C34: $*도매/숙박업종 PC | D34: 14 | E34: 1 | F34: =IFERROR(E34/D34,) -> 0.071428571 | G34: =IFERROR(H34/E34,0) -> 4884 | H34: 4884 | I34: 0 | J34: =IFERROR(I34/E34,0) -> 0 | K34: =IFERROR(H34/I34,0) -> 0
... B48: $페이파란 서브 파워링크(검색지면) | C48: $*교육/서비스업종 PC | D48: 68 | E48: 0 | F48: =IFERROR(E48/D48,) -> 0 | G48: =IFERROR(H48/E48,0) -> 0 | H48: 0 | I48: 0 | J48: =IFERROR(I48/E48,0) -> 0 | K48: =IFERROR(H48/I48,0) -> 0
B49: $페이파란 서브 파워링크(검색지면) | C49: $*요식업종 PC | D49: 53 | E49: 0 | H49: 0 | I49: 0
B51: TOTAL | D51: =SUM(D23:D50) -> 3632 | E51: =SUM(E23:E50) -> 123 | F51: =SUM(F23:F50) -> 1.1084499 | G51: =H51/E51 -> 6046.5122 | H51: =SUM(H23:H50) -> 743721 | I51: =SUM(I23:I50) -> 29 | J51: =IFERROR(I51/E51,0) -> 0.23577236 | K51: =IFERROR(H51/I51,0) -> 25645.552

Sheet 파워링크_키워드_평일
B2: 파워링크_키워드별 주간 데이터 (평일)
C6: * 기간 : 2026.03.02~2026.03.06
C8: 캠페인 | D8: 광고그룹 | E8: 키워드 | F8: 평균노출순위 | G8: 노출 | H8: 클릭 | I8: CTR | J8: CPC | K8: 광고비 | L8: 전환수 | M8: CVR | N8: 전환당 비용
C9: 합계 | D9: 합계 | E9: 총합 | F9: =SUM(F10:F1048576)/COUNTA(F10:F1048576) -> 2.8285714 | G9: =SUM(G10:G1048576) -> 1833 | H9: =SUM(H10:H1048576) -> 110 | I9: =H9/G9 -> 0.060010911 | J9: =K9/H9 -> 6372.3 | K9: =SUM(K10:K1048576) -> 700953 | L9: =SUM(L10:L1048576) -> 27 | M9: =L9/H9 -> 0.24545455 | N9: =IFERROR(K9/L9,0) -> 25961.222
C10: $페이파란 메인 파워링크(검색지면) | D10: $단말기MO (주간) | E10: 무선카드단말기 | F10: 2 | G10: 263 | H10: 17 | I10: =IFERROR(H10/G10,0) -> 0.064638783 | J10: =IFERROR(K10/H10,0) -> 8307.5882 | K10: 141229 | L10: 9 | M10: =IFERROR(L10/H10,0) -> 0.52941176 | N10: =IFERROR(K10/L10,0) -> 15692.111
C11: $페이파란 메인 파워링크(검색지면) | D11: $비사업자MO (주간) | E11: 휴대용카드단말기 | F11: 2.4 | G11: 253 | H11: 7 | I11: =IFERROR(H11/G11,0) -> 0.027667984 | J11: =IFERROR(K11/H11,0) -> 12360.857 | K11: 86526 | L11: 1 | M11: =IFERROR(L11/H11,0) -> 0.14285714 | N11: =IFERROR(K11/L11,0) -> 86526
C12: $페이파란 메인 파워링크(검색지면) | D12: $비사업자MO (주간) | E12: 비사업자카드단말기 | F12: 4.6 | G12: 78 | H12: 4 | I12: =IFERROR(H12/G12,0) -> 0.051282051 | J12: =IFERROR(K12/H12,0) -> 17839.25 | K12: 71357 | L12: 1 | M12: =IFERROR(L12/H12,0) -> 0.25 | N12: =IFERROR(K12/L12,0) -> 71357
C13: $페이파란 서브 파워링크(검색지면) | D13: $단말기 MO | E13: 카드단말기신청 | F13: 1.9 | G13: 45 | H13: 8 | I13: =IFERROR(H13/G13,0) -> 0.17777778 | J13: =IFERROR(K13/H13,0) -> 6583.5 | K13: 52668 | L13: 1 | M13: =IFERROR(L13/H13,0) -> 0.125 | N13: =IFERROR(K13/L13,0) -> 52668
C14: $페이파란 서브 파워링크(검색지면) | D14: $단말기 MO | E14: 카드체크기 | F14: 2.5 | G14: 80 | H14: 7 | I14: =IFERROR(H14/G14,0) -> 0.0875 | J14: =IFERROR(K14/H14,0) -> 6479 | K14: 45353 | L14: 0 | M14: =IFERROR(L14/H14,0) -> 0 | N14: =IFERROR(K14/L14,0) -> 0
C15: $페이파란 서브 파워링크(검색지면) | D15: $단말기 PC | E15: 카드단말기대여 | F15: 3.7 | G15: 58 | H15: 5 | I15: =IFERROR(H15/G15,0) -> 0.086206897 | J15: =IFERROR(K15/H15,0) -> 6441.6 | K15: 32208 | L15: 0 | M15: =IFERROR(L15/H15,0) -> 0 | N15: =IFERROR(K15/L15,0) -> 0
C16: $페이파란 서브 파워링크(검색지면) | D16: $단말기 MO | E16: 카드단말기대여 | F16: 3.7 | G16: 104 | H16: 4 | I16: =IFERROR(H16/G16,0) -> 0.038461538 | J16: =IFERROR(K16/H16,0) -> 8005.25 | K16: 32021 | L16: 1 | M16: =IFERROR(L16/H16,0) -> 0.25 | N16: =IFERROR(K16/L16,0) -> 32021
C17: $페이파란 메인 파워링크(검색지면) | D17: $단말기MO (야간) | E17: 신용카드단말기 | F17: 3.3 | G17: 50 | H17: 7 | I17: =IFERROR(H17/G17,0) -> 0.14 | J17: =IFERROR(K17/H17,0) -> 4354.4286 | K17: 30481 | L17: 1 | M17: =IFERROR(L17/H17,0) -> 0.14285714 | N17: =IFERROR(K17/L17,0) -> 30481
C18: $페이파란 서브 파워링크(검색지면) | D18: $단말기 PC | E18: 블루투스카드단말기 | F18: 1 | G18: 32 | H18: 4 | I18: =IFERROR(H18/G18,0) -> 0.125 | J18: =IFERROR(K18/H18,0) -> 4614.5 | K18: 18458 | L18: 0 | M18: =IFERROR(L18/H18,0) -> 0 | N18: =IFERROR(K18/L18,0) -> 0
C19: $페이파란 메인 파워링크(검색지면) | D19: $단말기PC (주간) | E19: 신용카드단말기 | F19: 4.5 | G19: 66 | H19: 2 | I19: =IFERROR(H19/G19,0) -> 0.03030303 | J19: =IFERROR(K19/H19,0) -> 8277.5 | K19: 16555 | L19: 0 | M19: =IFERROR(L19/H19,0) -> 0 | N19: =IFERROR(K19/L19,0) -> 0
C20: $페이파란 메인 파워링크(검색지면) | D20: $단말기MO (야간) | E20: 무선카드단말기 | F20: 2.9 | G20: 94 | H20: 6 | I20: =IFERROR(H20/G20,0) -> 0.063829787 | J20: =IFERROR(K20/H20,0) -> 2484.1667 | K20: 14905 | L20: 0 | M20: =IFERROR(L20/H20,0) -> 0 | N20: =IFERROR(K20/L20,0) -> 0
C21: $페이파란 메인 파워링크(검색지면) | D21: $단말기MO (주간) | E21: 유선카드단말기 | F21: 1.8 | G21: 38 | H21: 2 | I21: =IFERROR(H21/G21,0) -> 0.052631579 | J21: =IFERROR(K21/H21,0) -> 6435 | K21: 12870 | L21: 0 | M21: =IFERROR(L21/H21,0) -> 0 | N21: =IFERROR(K21/L21,0) -> 0
... C51: $페이파란 서브 파워링크(검색지면) | D51: $*병원업종 PC | E51: 단말기PG사VAN사차이 | F51: 3 | G51: 1 | H51: 1 | I51: =IFERROR(H51/G51,0) -> 1 | J51: =IFERROR(K51/H51,0) -> 55 | K51: 55 | L51: 0 | M51: =IFERROR(L51/H51,0) -> 0 | N51: =IFERROR(K51/L51,0) -> 0

Sheet 파워링크_키워드_주말
B2: 파워링크_키워드별 주간 데이터 (MO)
C6: * 기간 : 2026.03.07~2026.03.08
C8: 캠페인 | D8: 광고그룹 | E8: 키워드 | F8: 평균노출순위 | G8: 노출 | H8: 클릭 | I8: CTR | J8: CPC | K8: 광고비 | L8: 전환수 | M8: CVR | N8: 전환당 비용
C9: 합계 | D9: 합계 | E9: 총합 | F9: =SUM(F10:F1048576)/COUNTA(F10:F1048576) -> 2.4416667 | G9: =SUM(G10:G1048576) -> 185 | H9: =SUM(H10:H1048576) -> 13 | I9: =H9/G9 -> 0.07027027 | J9: =K9/H9 -> 3289.8462 | K9: =SUM(K10:K1048576) -> 42768 | L9: =SUM(L10:L1048576) -> 2 | M9: =L9/H9 -> 0.15384615 | N9: =IFERROR(K9/L9,0) -> 21384
C10: $페이파란 서브 파워링크(검색지면) | D10: $단말기 MO | E10: 카드체크기 | F10: 1.4 | G10: 16 | H10: 2 | I10: =IFERROR(H10/G10,0) -> 0.125 | J10: =IFERROR(K10/H10,0) -> 5126 | K10: 10252 | L10: 0 | M10: =IFERROR(L10/H10,0) -> 0 | N10: =IFERROR(K10/L10,0) -> 0
C11: $페이파란 메인 파워링크(검색지면) | D11: $비사업자MO (야간) | E11: 비사업자카드단말기 | F11: 4.2 | G11: 9 | H11: 1 | I11: =IFERROR(H11/G11,0) -> 0.11111111 | J11: =IFERROR(K11/H11,0) -> 7667 | K11: 7667 | L11: 1 | M11: =IFERROR(L11/H11,0) -> 1 | N11: =IFERROR(K11/L11,0) -> 7667
C12: $페이파란 서브 파워링크(검색지면) | D12: $단말기 PC | E12: 카드단말기교체 | F12: 2.5 | G12: 6 | H12: 1 | I12: =IFERROR(H12/G12,0) -> 0.16666667 | J12: =IFERROR(K12/H12,0) -> 7612 | K12: 7612 | L12: 0 | M12: =IFERROR(L12/H12,0) -> 0 | N12: =IFERROR(K12/L12,0) -> 0
C13: $페이파란 서브 파워링크(검색지면) | D13: $단말기 MO | E13: 카드결제기기 | F13: 1 | G13: 3 | H13: 1 | I13: =IFERROR(H13/G13,0) -> 0.33333333 | J13: =IFERROR(K13/H13,0) -> 4697 | K13: 4697 | L13: 0 | M13: =IFERROR(L13/H13,0) -> 0 | N13: =IFERROR(K13/L13,0) -> 0
C14: $페이파란 서브 파워링크(검색지면) | D14: $단말기 MO | E14: 카드단말기교체 | F14: 2.3 | G14: 67 | H14: 1 | I14: =IFERROR(H14/G14,0) -> 0.014925373 | J14: =IFERROR(K14/H14,0) -> 3982 | K14: 3982 | L14: 0 | M14: =IFERROR(L14/H14,0) -> 0 | N14: =IFERROR(K14/L14,0) -> 0
C15: $페이파란 서브 파워링크(검색지면) | D15: $*요식업종 MO | E15: 노점카드단말기 | F15: 1 | G15: 1 | H15: 1 | I15: =IFERROR(H15/G15,0) -> 1 | J15: =IFERROR(K15/H15,0) -> 2607 | K15: 2607 | L15: 1 | M15: =IFERROR(L15/H15,0) -> 1 | N15: =IFERROR(K15/L15,0) -> 2607
C16: $페이파란 서브 파워링크(검색지면) | D16: $단말기 MO | E16: 이동식카드단말기 | F16: 2.8 | G16: 37 | H16: 1 | I16: =IFERROR(H16/G16,0) -> 0.027027027 | J16: =IFERROR(K16/H16,0) -> 2002 | K16: 2002 | L16: 0 | M16: =IFERROR(L16/H16,0) -> 0 | N16: =IFERROR(K16/L16,0) -> 0
C17: $페이파란 서브 파워링크(검색지면) | D17: $단말기 MO | E17: 카드단말기대여 | F17: 3.1 | G17: 37 | H17: 1 | I17: =IFERROR(H17/G17,0) -> 0.027027027 | J17: =IFERROR(K17/H17,0) -> 1804 | K17: 1804 | L17: 0 | M17: =IFERROR(L17/H17,0) -> 0 | N17: =IFERROR(K17/L17,0) -> 0
C18: $페이파란 서브 파워링크(검색지면) | D18: $*스포츠 및 여가 MO | E18: 노래방카드단말기 | F18: 4 | G18: 2 | H18: 1 | I18: =IFERROR(H18/G18,0) -> 0.5 | J18: =IFERROR(K18/H18,0) -> 990 | K18: 990 | L18: 0 | M18: =IFERROR(L18/H18,0) -> 0 | N18: =IFERROR(K18/L18,0) -> 0
C19: $페이파란 서브 파워링크(검색지면) | D19: $*도매/숙박업종 MO | E19: 플리마켓카드단말기 | F19: 2 | G19: 3 | H19: 1 | I19: =IFERROR(H19/G19,0) -> 0.33333333 | J19: =IFERROR(K19/H19,0) -> 517 | K19: 517 | L19: 0 | M19: =IFERROR(L19/H19,0) -> 0 | N19: =IFERROR(K19/L19,0) -> 0
C20: $페이파란 서브 파워링크(검색지면) | D20: $*병원업종 PC | E20: 병원PG단말기 | F20: 1 | G20: 1 | H20: 1 | I20: =IFERROR(H20/G20,0) -> 1 | J20: =IFERROR(K20/H20,0) -> 517 | K20: 517 | L20: 0 | M20: =IFERROR(L20/H20,0) -> 0 | N20: =IFERROR(K20/L20,0) -> 0
C21: $페이파란 서브 파워링크(검색지면) | D21: $*도매/숙박업종 MO | E21: 꽃집단말기 | F21: 4 | G21: 3 | H21: 1 | I21: =IFERROR(H21/G21,0) -> 0.33333333 | J21: =IFERROR(K21/H21,0) -> 121 | K21: 121 | L21: 0 | M21: =IFERROR(L21/H21,0) -> 0 | N21: =IFERROR(K21/L21,0) -> 0

Sheet 파워링크_소재별_주간
B2: 파워링크_소재별 주간 데이터
C7: * 기간 : 2026.03.02~2026.03.08
C9: 소재 | D9: 캠페인 | E9: 광고그룹 | F9: 노출 | G9: 클릭 | H9: CTR | I9: CPC | J9: 광고비 | K9: 전환수 | L9: CVR | O9: 소재
E10: 합계 | F10: =SUM(F11:F1048576) -> 3579 | G10: =SUM(G11:G1048576) -> 123 | H10: =G10/F10 -> 0.034367142 | I10: =J10/G10 -> 6046.5122 | J10: =SUM(J11:J1048576) -> 743721 | K10: =SUM(K11:K1048576) -> 29 | L10: =K10/G10 -> 0.23577236 | N10: 단말기 소재1
B11: nad-a001-01-000000374150087 | C11: =VLOOKUP(B11,'파링_소재 RAW'!I:J,2,) -> 단말기 소재2 | D11: $페이파란 서브 파워링크(검색지면) | E11: $단말기 MO | F11: 488 | G11: 19 | H11: =IFERROR(G11/F11,0) -> 0.038934426 | I11: =IFERROR(J11/G11,0) -> 6005.4211 | J11: 114103 | K11: 3 | L11: =IFERROR(K11/G11,0) -> 0.15789474
B12: nad-a001-01-000000419812527 | C12: =VLOOKUP(B12,'파링_소재 RAW'!I:J,2,) -> 비사업자 소재5 | D12: $페이파란 메인 파워링크(검색지면) | E12: $비사업자MO (주간) | F12: 168 | G12: 6 | H12: =IFERROR(G12/F12,0) -> 0.035714286 | I12: =IFERROR(J12/G12,0) -> 15310.167 | J12: 91861 | K12: 1 | L12: =IFERROR(K12/G12,0) -> 0.16666667 | N12: 단말기 소재2
B13: nad-a001-01-000000419820895 | C13: =VLOOKUP(B13,'파링_소재 RAW'!I:J,2,) -> 단말기 소재4 | D13: $페이파란 메인 파워링크(검색지면) | E13: $단말기MO (주간) | F13: 141 | G13: 10 | H13: =IFERROR(G13/F13,0) -> 0.070921986 | I13: =IFERROR(J13/G13,0) -> 8104.8 | J13: 81048 | K13: 4 | L13: =IFERROR(K13/G13,0) -> 0.4
B14: nad-a001-01-000000419832465 | C14: =VLOOKUP(B14,'파링_소재 RAW'!I:J,2,) -> 단말기 소재3 | D14: $페이파란 메인 파워링크(검색지면) | E14: $단말기MO (주간) | F14: 169 | G14: 9 | H14: =IFERROR(G14/F14,0) -> 0.053254438 | I14: =IFERROR(J14/G14,0) -> 8116.7778 | J14: 73051 | K14: 5 | L14: =IFERROR(K14/G14,0) -> 0.55555556 | N14: 단말기 소재3
B15: nad-a001-01-000000374120874 | C15: =VLOOKUP(B15,'파링_소재 RAW'!I:J,2,) -> 단말기 소재1 | D15: $페이파란 서브 파워링크(검색지면) | E15: $단말기 MO | F15: 502 | G15: 14 | H15: =IFERROR(G15/F15,0) -> 0.027888446 | I15: =IFERROR(J15/G15,0) -> 5122.0714 | J15: 71709 | K15: 1 | L15: =IFERROR(K15/G15,0) -> 0.071428571
B16: nad-a001-01-000000419815565 | C16: =VLOOKUP(B16,'파링_소재 RAW'!I:J,2,) -> 비사업자 소재6 | D16: $페이파란 메인 파워링크(검색지면) | E16: $비사업자MO (주간) | F16: 176 | G16: 5 | H16: =IFERROR(G16/F16,0) -> 0.028409091 | I16: =IFERROR(J16/G16,0) -> 13204.4 | J16: 66022 | K16: 1 | L16: =IFERROR(K16/G16,0) -> 0.2 | N16: 단말기 소재3-1
B17: nad-a001-01-000000374150300 | C17: =VLOOKUP(B17,'파링_소재 RAW'!I:J,2,) -> 단말기 소재2 | D17: $페이파란 서브 파워링크(검색지면) | E17: $단말기 PC | F17: 147 | G17: 7 | H17: =IFERROR(G17/F17,0) -> 0.047619048 | I17: =IFERROR(J17/G17,0) -> 5746.7143 | J17: 40227 | K17: 0 | L17: =IFERROR(K17/G17,0) -> 0
B18: nad-a001-01-000000419832449 | C18: =VLOOKUP(B18,'파링_소재 RAW'!I:J,2,) -> 단말기 소재3 | D18: $페이파란 메인 파워링크(검색지면) | E18: $단말기MO (야간) | F18: 105 | G18: 9 | H18: =IFERROR(G18/F18,0) -> 0.085714286 | I18: =IFERROR(J18/G18,0) -> 3927 | J18: 35343 | K18: 1 | L18: =IFERROR(K18/G18,0) -> 0.11111111 | N18: 단말기 소재4
B19: nad-a001-01-000000374120875 | C19: =VLOOKUP(B19,'파링_소재 RAW'!I:J,2,) -> 단말기 소재1 | D19: $페이파란 서브 파워링크(검색지면) | E19: $단말기 PC | F19: 165 | G19: 6 | H19: =IFERROR(G19/F19,0) -> 0.036363636 | I19: =IFERROR(J19/G19,0) -> 5764 | J19: 34584 | K19: 2 | L19: =IFERROR(K19/G19,0) -> 0.33333333
B20: nad-a001-01-000000419832521 | C20: =VLOOKUP(B20,'파링_소재 RAW'!I:J,2,) -> 단말기 소재3 | D20: $페이파란 메인 파워링크(검색지면) | E20: $단말기PC (주간) | F20: 136 | G20: 3 | H20: =IFERROR(G20/F20,0) -> 0.022058824 | I20: =IFERROR(J20/G20,0) -> 8499.3333 | J20: 25498 | K20: 1 | L20: =IFERROR(K20/G20,0) -> 0.33333333 | N20: 비사업자 소재1
B21: nad-a001-01-000000419820861 | C21: =VLOOKUP(B21,'파링_소재 RAW'!I:J,2,) -> 단말기 소재4 | D21: $페이파란 메인 파워링크(검색지면) | E21: $단말기MO (야간) | F21: 102 | G21: 6 | H21: =IFERROR(G21/F21,0) -> 0.058823529 | I21: =IFERROR(J21/G21,0) -> 3767.5 | J21: 22605 | K21: 0 | L21: =IFERROR(K21/G21,0) -> 0
B22: nad-a001-01-000000419811478 | C22: =VLOOKUP(B22,'파링_소재 RAW'!I:J,2,) -> 비사업자 소재5 | D22: $페이파란 메인 파워링크(검색지면) | E22: $비사업자MO (야간) | F22: 60 | G22: 3 | H22: =IFERROR(G22/F22,0) -> 0.05 | I22: =IFERROR(J22/G22,0) -> 5650.3333 | J22: 16951 | K22: 1 | L22: =IFERROR(K22/G22,0) -> 0.33333333 | N22: 비사업자 소재2
B23: nad-a001-01-000000419832513 | C23: =VLOOKUP(B23,'파링_소재 RAW'!I:J,2,) -> 단말기 소재3 | D23: $페이파란 메인 파워링크(검색지면) | E23: $단말기PC (야간) | F23: 32 | G23: 3 | H23: =IFERROR(G23/F23,0) -> 0.09375 | I23: =IFERROR(J23/G23,0) -> 4847.3333 | J23: 14542 | K23: 0 | L23: =IFERROR(K23/G23,0) -> 0
B24: nad-a001-01-000000419832431 | C24: =VLOOKUP(B24,'파링_소재 RAW'!I:J,2,) -> 단말기 소재3 | D24: $페이파란 메인 파워링크(검색지면) | E24: $단말기(주간)_다음 | F24: 15 | G24: 3 | H24: =IFERROR(G24/F24,0) -> 0.2 | I24: =IFERROR(J24/G24,0) -> 3846.3333 | J24: 11539 | K24: 1 | L24: =IFERROR(K24/G24,0) -> 0.33333333 | N24: 비사업자 소재3
B25: nad-a001-01-000000419820849 | C25: =VLOOKUP(B25,'파링_소재 RAW'!I:J,2,) -> 단말기 소재4 | D25: $페이파란 메인 파워링크(검색지면) | E25: $단말기(주간)_다음 | F25: 13 | G25: 1 | H25: =IFERROR(G25/F25,0) -> 0.076923077 | I25: =IFERROR(J25/G25,0) -> 8063 | J25: 8063 | K25: 0 | L25: =IFERROR(K25/G25,0) -> 0
B26: nad-a001-01-000000419812613 | C26: =VLOOKUP(B26,'파링_소재 RAW'!I:J,2,) -> 비사업자 소재5 | D26: $페이파란 메인 파워링크(검색지면) | E26: $비사업자PC (주간) | F26: 90 | G26: 1 | H26: =IFERROR(G26/F26,0) -> 0.011111111 | I26: =IFERROR(J26/G26,0) -> 7876 | J26: 7876 | K26: 0 | L26: =IFERROR(K26/G26,0) -> 0 | N26: 비사업자 소재4
B27: nad-a001-01-000000386910910 | C27: =VLOOKUP(B27,'파링_소재 RAW'!I:J,2,) -> 요식 소재3 | D27: $페이파란 서브 파워링크(검색지면) | E27: $*요식업종 MO | F27: 163 | G27: 2 | H27: =IFERROR(G27/F27,0) -> 0.012269939 | I27: =IFERROR(J27/G27,0) -> 3047 | J27: 6094 | K27: 1 | L27: =IFERROR(K27/G27,0) -> 0.5
B28: nad-a001-01-000000374120891 | C28: =VLOOKUP(B28,'파링_소재 RAW'!I:J,2,) -> 도매/숙박 소재2 | D28: $페이파란 서브 파워링크(검색지면) | E28: $*도매/숙박업종 PC | F28: 10 | G28: 1 | H28: =IFERROR(G28/F28,0) -> 0.1 | I28: =IFERROR(J28/G28,0) -> 4884 | J28: 4884 | K28: 0 | L28: =IFERROR(K28/G28,0) -> 0 | N28: 비사업자 소재5
B29: nad-a001-01-000000374120907 | C29: =VLOOKUP(B29,'파링_소재 RAW'!I:J,2,) -> 요식 소재1 | D29: $페이파란 서브 파워링크(검색지면) | E29: $*요식업종 MO | F29: 152 | G29: 1 | H29: =IFERROR(G29/F29,0) -> 0.0065789474 | I29: =IFERROR(J29/G29,0) -> 4246 | J29: 4246 | K29: 0 | L29: =IFERROR(K29/G29,0) -> 0
B30: nad-a001-01-000000386910931 | C30: =VLOOKUP(B30,'파링_소재 RAW'!I:J,2,) -> 요식 소재3 | D30: $페이파란 서브 파워링크(검색지면) | E30: $*요식업종 PC | F30: 28 | G30: 1 | H30: =IFERROR(G30/F30,0) -> 0.035714286 | I30: =IFERROR(J30/G30,0) -> 3388 | J30: 3388 | K30: 0 | L30: =IFERROR(K30/G30,0) -> 0 | N30: 비사업자 소재6
B31: nad-a001-01-000000404095705 | C31: =VLOOKUP(B31,'파링_소재 RAW'!I:J,2,) -> 즉시 소재1 | D31: $페이파란 메인 파워링크(검색지면) | E31: $즉시MO (야간) | F31: 10 | G31: 2 | H31: =IFERROR(G31/F31,0) -> 0.2 | I31: =IFERROR(J31/G31,0) -> 1518 | J31: 3036 | K31: 2 | L31: =IFERROR(K31/G31,0) -> 1
B32: nad-a001-01-000000374120886 | C32: =VLOOKUP(B32,'파링_소재 RAW'!I:J,2,) -> 도매/숙박 소재1 | D32: $페이파란 서브 파워링크(검색지면) | E32: $*도매/숙박업종 MO | F32: 19 | G32: 2 | H32: =IFERROR(G32/F32,0) -> 0.10526316 | I32: =IFERROR(J32/G32,0) -> 995.5 | J32: 1991 | K32: 0 | L32: =IFERROR(K32/G32,0) -> 0 | N32: 수기 소재1
B33: nad-a001-01-000000386911025 | C33: =VLOOKUP(B33,'파링_소재 RAW'!I:J,2,) -> 차량 소재3 | D33: $페이파란 서브 파워링크(검색지면) | E33: $*차량업종 PC | F33: 35 | G33: 2 | H33: =IFERROR(G33/F33,0) -> 0.057142857 | I33: =IFERROR(J33/G33,0) -> 902 | J33: 1804 | K33: 1 | L33: =IFERROR(K33/G33,0) -> 0.5
B34: nad-a001-01-000000374120901 | C34: =VLOOKUP(B34,'파링_소재 RAW'!I:J,2,) -> 스포츠/여가 소재2 | D34: $페이파란 서브 파워링크(검색지면) | E34: $*스포츠 및 여가 MO | F34: 5 | G34: 1 | H34: =IFERROR(G34/F34,0) -> 0.2 | I34: =IFERROR(J34/G34,0) -> 990 | J34: 990 | K34: 0 | L34: =IFERROR(K34/G34,0) -> 0 | N34: 수기 소재2
B35: nad-a001-01-000000374120897 | C35: =VLOOKUP(B35,'파링_소재 RAW'!I:J,2,) -> 병원 소재2 | D35: $페이파란 서브 파워링크(검색지면) | E35: $*병원업종 PC | F35: 34 | G35: 1 | H35: =IFERROR(G35/F35,0) -> 0.029411765 | I35: =IFERROR(J35/G35,0) -> 594 | J35: 594 | K35: 0 | L35: =IFERROR(K35/G35,0) -> 0
B36: nad-a001-01-000000331481812 | C36: =VLOOKUP(B36,'파링_소재 RAW'!I:J,2,) -> 병원 소재1 | D36: $페이파란 서브 파워링크(검색지면) | E36: $*병원업종 PC | F36: 21 | G36: 2 | H36: =IFERROR(G36/F36,0) -> 0.095238095 | I36: =IFERROR(J36/G36,0) -> 286 | J36: 572 | K36: 0 | L36: =IFERROR(K36/G36,0) -> 0 | N36: 카카오
B37: nad-a001-01-000000374120887 | C37: =VLOOKUP(B37,'파링_소재 RAW'!I:J,2,) -> 도매/숙박 소재2 | D37: $페이파란 서브 파워링크(검색지면) | E37: $*도매/숙박업종 MO | F37: 18 | G37: 1 | H37: =IFERROR(G37/F37,0) -> 0.055555556 | I37: =IFERROR(J37/G37,0) -> 517 | J37: 517 | K37: 0 | L37: =IFERROR(K37/G37,0) -> 0
B38: nad-a001-01-000000374120893 | C38: =VLOOKUP(B38,'파링_소재 RAW'!I:J,2,) -> 병원 소재2 | D38: $페이파란 서브 파워링크(검색지면) | E38: $*병원업종 MO | F38: 26 | G38: 1 | H38: =IFERROR(G38/F38,0) -> 0.038461538 | I38: =IFERROR(J38/G38,0) -> 297 | J38: 297 | K38: 2 | L38: =IFERROR(K38/G38,0) -> 2 | N38: 교육/서비스 소재1
B39: nad-a001-01-000000331481683 | C39: =VLOOKUP(B39,'파링_소재 RAW'!I:J,2,) -> 병원 소재1 | D39: $페이파란 서브 파워링크(검색지면) | E39: $*병원업종 MO | F39: 16 | G39: 1 | H39: =IFERROR(G39/F39,0) -> 0.0625 | I39: =IFERROR(J39/G39,0) -> 286 | J39: 286 | K39: 0 | L39: =IFERROR(K39/G39,0) -> 0
B40: nad-a001-01-000000374120878 | C40: =VLOOKUP(B40,'파링_소재 RAW'!I:J,2,) -> 교육/서비스 소재1 | D40: $페이파란 서브 파워링크(검색지면) | E40: $*교육/서비스업종 MO | F40: 19 | G40: 0 | H40: =IFERROR(G40/F40,0) -> 0 | I40: =IFERROR(J40/G40,0) -> 0 | J40: 0 | K40: 0 | L40: =IFERROR(K40/G40,0) -> 0 | N40: 교육/서비스 소재2
B41: nad-a001-01-000000374120879 | C41: =VLOOKUP(B41,'파링_소재 RAW'!I:J,2,) -> 교육/서비스 소재2 | D41: $페이파란 서브 파워링크(검색지면) | E41: $*교육/서비스업종 MO | F41: 23 | G41: 0 | H41: =IFERROR(G41/F41,0) -> 0 | I41: =IFERROR(J41/G41,0) -> 0 | J41: 0 | K41: 0 | L41: =IFERROR(K41/G41,0) -> 0
B42: nad-a001-01-000000374120881 | C42: =VLOOKUP(B42,'파링_소재 RAW'!I:J,2,) -> 교육/서비스 소재1 | D42: $페이파란 서브 파워링크(검색지면) | E42: $*교육/서비스업종 PC | F42: 33 | G42: 0 | H42: =IFERROR(G42/F42,0) -> 0 | I42: =IFERROR(J42/G42,0) -> 0 | J42: 0 | K42: 0 | L42: =IFERROR(K42/G42,0) -> 0 | N42: 도매/숙박 소재1
B43: nad-a001-01-000000374120883 | C43: =VLOOKUP(B43,'파링_소재 RAW'!I:J,2,) -> 교육/서비스 소재2 | D43: $페이파란 서브 파워링크(검색지면) | E43: $*교육/서비스업종 PC | F43: 35 | G43: 0 | H43: =IFERROR(G43/F43,0) -> 0 | I43: =IFERROR(J43/G43,0) -> 0 | J43: 0 | K43: 0 | L43: =IFERROR(K43/G43,0) -> 0
B44: nad-a001-01-000000374120889 | C44: =VLOOKUP(B44,'파링_소재 RAW'!I:J,2,) -> 도매/숙박 소재1 | D44: $페이파란 서브 파워링크(검색지면) | E44: $*도매/숙박업종 PC | F44: 4 | G44: 0 | H44: =IFERROR(G44/F44,0) -> 0 | I44: =IFERROR(J44/G44,0) -> 0 | J44: 0 | K44: 0 | L44: =IFERROR(K44/G44,0) -> 0 | N44: 도매/숙박 소재2
B45: nad-a001-01-000000374120899 | C45: =VLOOKUP(B45,'파링_소재 RAW'!I:J,2,) -> 스포츠/여가 소재1 | D45: $페이파란 서브 파워링크(검색지면) | E45: $*스포츠 및 여가 MO | F45: 2 | G45: 0 | H45: =IFERROR(G45/F45,0) -> 0 | I45: =IFERROR(J45/G45,0) -> 0 | J45: 0 | K45: 0 | L45: =IFERROR(K45/G45,0) -> 0
B46: nad-a001-01-000000374120903 | C46: =VLOOKUP(B46,'파링_소재 RAW'!I:J,2,) -> 스포츠/여가 소재1 | D46: $페이파란 서브 파워링크(검색지면) | E46: $*스포츠 및 여가 PC | F46: 1 | G46: 0 | H46: =IFERROR(G46/F46,0) -> 0 | I46: =IFERROR(J46/G46,0) -> 0 | J46: 0 | K46: 0 | L46: =IFERROR(K46/G46,0) -> 0 | N46: 병원 소재1
...

Sheet 파링_소재 RAW
A1: 소재 | B1: 캠페인 | C1: 광고그룹 | D1: 노출수 | E1: 클릭수 | F1: 총비용(VAT포함,원) | G1: 전환수 | I1: 소재 ID (누적) | J1: 소재명
A2: nad-a001-01-000000374150087 | B2: $페이파란 서브 파워링크(검색지면) | C2: $단말기 MO | D2: 488 | E2: 19 | F2: 114103 | G2: 3 | I2: nad-a001-01-000000296429846 | J2: 단말기 소재1
A3: nad-a001-01-000000419812527 | B3: $페이파란 메인 파워링크(검색지면) | C3: $비사업자MO (주간) | D3: 168 | E3: 6 | F3: 91861 | G3: 1 | I3: nad-a001-01-000000294607693 | J3: 수기 소재1
A4: nad-a001-01-000000419820895 | B4: $페이파란 메인 파워링크(검색지면) | C4: $단말기MO (주간) | D4: 141 | E4: 10 | F4: 81048 | G4: 4 | I4: nad-a001-01-000000296429855 | J4: 수기 소재1
A5: nad-a001-01-000000419832465 | B5: $페이파란 메인 파워링크(검색지면) | C5: $단말기MO (주간) | D5: 169 | E5: 9 | F5: 73051 | G5: 5 | I5: nad-a001-01-000000296429851 | J5: 비사업자 소재1
A6: nad-a001-01-000000374120874 | B6: $페이파란 서브 파워링크(검색지면) | C6: $단말기 MO | D6: 502 | E6: 14 | F6: 71709 | G6: 1 | I6: nad-a001-01-000000292775481 | J6: 단말기 소재2
A7: nad-a001-01-000000419815565 | B7: $페이파란 메인 파워링크(검색지면) | C7: $비사업자MO (주간) | D7: 176 | E7: 5 | F7: 66022 | G7: 1 | I7: nad-a001-01-000000293191159 | J7: 단말기 소재1
A8: nad-a001-01-000000374150300 | B8: $페이파란 서브 파워링크(검색지면) | C8: $단말기 PC | D8: 147 | E8: 7 | F8: 40227 | G8: 0 | I8: nad-a001-01-000000293976798 | J8: 비사업자 소재1
A9: nad-a001-01-000000419832449 | B9: $페이파란 메인 파워링크(검색지면) | C9: $단말기MO (야간) | D9: 105 | E9: 9 | F9: 35343 | G9: 1 | I9: nad-a001-01-000000293169289 | J9: 단말기 소재2
A10: nad-a001-01-000000374120875 | B10: $페이파란 서브 파워링크(검색지면) | C10: $단말기 PC | D10: 165 | E10: 6 | F10: 34584 | G10: 2 | I10: nad-a001-01-000000296429847 | J10: 단말기 소재2
A11: nad-a001-01-000000419832521 | B11: $페이파란 메인 파워링크(검색지면) | C11: $단말기PC (주간) | D11: 136 | E11: 3 | F11: 25498 | G11: 1 | I11: nad-a001-01-000000296429952 | J11: 단말기 소재1
A12: nad-a001-01-000000419820861 | B12: $페이파란 메인 파워링크(검색지면) | C12: $단말기MO (야간) | D12: 102 | E12: 6 | F12: 22605 | G12: 0 | I12: nad-a001-01-000000297114040 | J12: 비사업자 소재1
A13: nad-a001-01-000000419811478 | B13: $페이파란 메인 파워링크(검색지면) | C13: $비사업자MO (야간) | D13: 60 | E13: 3 | F13: 16951 | G13: 1 | I13: nad-a001-01-000000293169292 | J13: 비사업자 소재1
... A53: nad-a001-01-000000419821009 | B53: $페이파란 메인 파워링크(검색지면) | C53: $단말기PC (주간) | D53: 122 | E53: 0 | F53: 0 | G53: 2 | I53: nad-a001-01-000000297994073 | J53: 도매/숙박 소재1
I54: nad-a001-01-000000297994074 | J54: 도매/숙박 소재2
I55: nad-a001-01-000000297994076 | J55: 도매/숙박 소재2
I56: nad-a001-01-000000297994079 | J56: 병원 소재1
I57: nad-a001-01-000000297994083 | J57: 병원 소재1
I58: nad-a001-01-000000297994084 | J58: 병원 소재2
I59: nad-a001-01-000000297994144 | J59: 요식업 소재1
I60: nad-a001-01-000000297994148 | J60: 요식업 소재2
I61: nad-a001-01-000000297994164 | J61: 요식업 소재1
I62: nad-a001-01-000000297994167 | J62: 요식업 소재2
I63: nad-a001-01-000000297994174 | J63: 요식업 소재1
I64: nad-a001-01-000000297994185 | J64: 운동 소재1
I65: nad-a001-01-000000297994191 | J65: 차량 소재1
... I410: nad-a001-01-000000419832521 | J410: 단말기 소재3

Sheet 파워링크 RAW
A1: 일자 | B1: 기기 | C1: 캠페인 | D1: 매체 | E1: 노출 | F1: 클릭 | G1: 광고비 | H1: 구매수 | I1: 매출액
A2: 2026.01.02. | B2: PC | C2: $페이파란 메인 파워링크(검색지면) | D2: 파워링크 | E2: 288 | F2: 7 | G2: 55616 | H2: 2
A3: 2026.01.05. | B3: PC | C3: $페이파란 메인 파워링크(검색지면) | D3: 파워링크 | E3: 342 | F3: 11 | G3: 95381 | H3: 0
A4: 2026.01.06. | B4: PC | C4: $페이파란 메인 파워링크(검색지면) | D4: 파워링크 | E4: 414 | F4: 7 | G4: 69454 | H4: 1
A5: 2026.01.07. | B5: PC | C5: $페이파란 메인 파워링크(검색지면) | D5: 파워링크 | E5: 278 | F5: 8 | G5: 76131 | H5: 2
A6: 2026.01.08. | B6: PC | C6: $페이파란 메인 파워링크(검색지면) | D6: 파워링크 | E6: 356 | F6: 7 | G6: 52558 | H6: 0
A7: 2026.01.09. | B7: PC | C7: $페이파란 메인 파워링크(검색지면) | D7: 파워링크 | E7: 336 | F7: 4 | G7: 31097 | H7: 0
A8: 2026.01.12. | B8: PC | C8: $페이파란 메인 파워링크(검색지면) | D8: 파워링크 | E8: 431 | F8: 10 | G8: 79662 | H8: 0
A9: 2026.01.13. | B9: PC | C9: $페이파란 메인 파워링크(검색지면) | D9: 파워링크 | E9: 189 | F9: 4 | G9: 31185 | H9: 1
A10: 2026.01.14. | B10: PC | C10: $페이파란 메인 파워링크(검색지면) | D10: 파워링크 | E10: 252 | F10: 2 | G10: 10593 | H10: 0
A11: 2026.01.15. | B11: PC | C11: $페이파란 메인 파워링크(검색지면) | D11: 파워링크 | E11: 406 | F11: 6 | G11: 44385 | H11: 1
A12: 2026.01.16. | B12: PC | C12: $페이파란 메인 파워링크(검색지면) | D12: 파워링크 | E12: 297 | F12: 4 | G12: 40546 | H12: 1
A13: 2026.01.19. | B13: PC | C13: $페이파란 메인 파워링크(검색지면) | D13: 파워링크 | E13: 376 | F13: 8 | G13: 60280 | H13: 4
... A237: 2026.03.08. | B237: 모바일 | C237: $페이파란 서브 파워링크(검색지면) | D237: 파워링크 | E237: 183 | F237: 5 | G237: 13079 | H237: 0

Sheet 카카오_Summary
B2: 카카오 검색광고
B4: =파워링크_Summary!B4 -> 구분 (1/1~1/31) | C4: 노출 | D4: 클릭 | E4: 광고비 (vat 포함) | F4: 전환수
B5: 누적 달성량 | C5: =C54 -> 0 | D5: =D54 -> 0 | E5: =G54 -> 0 | F5: =H54 -> 0
B7: ▶ 성과 추이
B32: ▶ 주차별 Total 성과
B33: 주차 | C33: 노출수 | D33: 클릭수 | E33: CTR | F33: CPC | G33: 광고비 | H33: 매출
H34: 전환수 | I34: CVR | J34: 전환당 비용
B35: =파워링크_Summary!B35 -> 1월 1주차 (1~4일) | C35: =SUM(C55:C61) -> 0 | D35: =SUM(D55:D61) -> 0 | E35: =IFERROR(D35/C35,) -> 0 | F35: =IFERROR(G35/D35,0) -> 0 | G35: =SUM(G55:G61) -> 0 | H35: =SUM(H55:H61) -> 0 | I35: =IFERROR(H35/D35,0) -> 0 | J35: =IFERROR(G35/H35,0) -> 0
B36: =파워링크_Summary!B36 -> 2/9 ~ 2/15 | C36: =SUM(C62:C68) -> 0 | D36: =SUM(D62:D68) -> 0 | E36: =IFERROR(D36/C36,) -> 0 | F36: =IFERROR(G36/D36,0) -> 0 | G36: =SUM(G62:G68) -> 0 | H36: =SUM(H62:H68) -> 0 | I36: =IFERROR(H36/D36,0) -> 0 | J36: =IFERROR(G36/H36,0) -> 0
B37: =파워링크_Summary!B37 -> 2/16 ~ 2/22 | C37: =SUM(C69:C75) -> 0 | D37: =SUM(D69:D75) -> 0 | E37: =IFERROR(D37/C37,) -> 0 | F37: =IFERROR(G37/D37,0) -> 0 | G37: =SUM(G69:G75) -> 0 | H37: =SUM(H69:H75) -> 0 | I37: =IFERROR(H37/D37,0) -> 0 | J37: =IFERROR(G37/H37,0) -> 0
B38: =파워링크_Summary!B38 -> 2/23 ~ 3/1 | C38: =SUM(C76:C82) -> 0 | D38: =SUM(D76:D82) -> 0 | E38: =IFERROR(D38/C38,) -> 0 | F38: =IFERROR(G38/D38,0) -> 0 | G38: =SUM(G76:G82) -> 0 | H38: =SUM(H76:H82) -> 0 | I38: =IFERROR(H38/D38,0) -> 0 | J38: =IFERROR(G38/H38,0) -> 0
B39: =파워링크_Summary!B39 -> 3/2 ~ 3/8 | C39: =SUM(C83:C85) -> 0 | D39: =SUM(D83:D85) -> 0 | E39: =IFERROR(D39/C39,) -> 0 | F39: =IFERROR(G39/D39,0) -> 0 | G39: =SUM(G83:G85) -> 0 | H39: =SUM(H83:H85) -> 0 | I39: =IFERROR(H39/D39,0) -> 0 | J39: =IFERROR(G39/H39,0) -> 0
B40: 전주대비 | C40: =IFERROR(C38/C37-1,"-") -> - | D40: =IFERROR(D37/D36-1,"-") -> - | E40: =IFERROR(E37/E36-1,"-") -> - | F40: =IFERROR(F37/F36-1,"-") -> - | G40: =IFERROR(G37/G36-1,"-") -> - | H40: =IFERROR(H37/H36-1,"-") -> - | I40: =IFERROR(I37/I36-1,"-") -> - | J40: =IFERROR(J37/J36-1,"-") -> -
B42: ▶ 상품 별 성과
B43: 구분 | C43: 노출수 | D43: 클릭수 | E43: 클릭률 | F43: CPC | G43: 광고비 | H43: 매출
H44: 구매수 | I44: 구매 전환율 | J44: 구매 전환당 비용
B45: 시트 | C45: =SUMIFS(#REF!,#REF!,"파워링크",#REF!,카카오_Summary!$B45) -> #REF! | D45: =SUMIFS(#REF!,#REF!,"파워링크",#REF!,카카오_Summary!$B45) -> #REF! | E45: =IFERROR(D45/C45,) -> 0 | F45: =IFERROR(G45/D45,0) -> 0 | G45: =SUMIFS(#REF!,#REF!,"파워링크",#REF!,카카오_Summary!$B45) -> #REF! | H45: =SUMIFS(#REF!,#REF!,카카오_Summary!$B45,#REF!,"파워링크") -> #REF! | I45: =IFERROR(H45/D45,0) -> 0 | J45: =IFERROR(G45/H45,0) -> 0
B46: 베개 | C46: =SUMIFS(#REF!,#REF!,"파워링크",#REF!,카카오_Summary!$B46) -> #REF! | D46: =SUMIFS(#REF!,#REF!,"파워링크",#REF!,카카오_Summary!$B46) -> #REF! | E46: =IFERROR(D46/C46,) -> 0 | F46: =IFERROR(G46/D46,0) -> 0 | G46: =SUMIFS(#REF!,#REF!,"파워링크",#REF!,카카오_Summary!$B46) -> #REF! | H46: =SUMIFS(#REF!,#REF!,카카오_Summary!$B46,#REF!,"파워링크") -> #REF! | I46: =IFERROR(H46/D46,0) -> 0 | J46: =IFERROR(G46/H46,0) -> 0
B47: 토퍼 | C47: =SUMIFS(#REF!,#REF!,"파워링크",#REF!,카카오_Summary!$B47) -> #REF! | D47: =SUMIFS(#REF!,#REF!,"파워링크",#REF!,카카오_Summary!$B47) -> #REF! | E47: =IFERROR(D47/C47,) -> 0 | F47: =IFERROR(G47/D47,0) -> 0 | G47: =SUMIFS(#REF!,#REF!,"파워링크",#REF!,카카오_Summary!$B47) -> #REF! | H47: =SUMIFS(#REF!,#REF!,카카오_Summary!$B47,#REF!,"파워링크") -> #REF! | I47: =IFERROR(H47/D47,0) -> 0 | J47: =IFERROR(G47/H47,0) -> 0
B48: 인솔 | C48: =SUMIFS(#REF!,#REF!,"파워링크",#REF!,카카오_Summary!$B48) -> #REF! | D48: =SUMIFS(#REF!,#REF!,"파워링크",#REF!,카카오_Summary!$B48) -> #REF! | E48: =IFERROR(D48/C48,) -> 0 | F48: =IFERROR(G48/D48,0) -> 0 | G48: =SUMIFS(#REF!,#REF!,"파워링크",#REF!,카카오_Summary!$B48) -> #REF! | H48: =SUMIFS(#REF!,#REF!,카카오_Summary!$B48,#REF!,"파워링크") -> #REF! | I48: =IFERROR(H48/D48,0) -> 0 | J48: =IFERROR(G48/H48,0) -> 0
B49: 브랜드 | C49: =SUMIFS(#REF!,#REF!,"파워링크",#REF!,카카오_Summary!$B49) -> #REF! | D49: =SUMIFS(#REF!,#REF!,"파워링크",#REF!,카카오_Summary!$B49) -> #REF! | E49: =IFERROR(D49/C49,) -> 0 | F49: =IFERROR(G49/D49,0) -> 0 | G49: =SUMIFS(#REF!,#REF!,"파워링크",#REF!,카카오_Summary!$B49) -> #REF! | H49: =SUMIFS(#REF!,#REF!,카카오_Summary!$B49,#REF!,"파워링크") -> #REF! | I49: =IFERROR(H49/D49,0) -> 0 | J49: =IFERROR(G49/H49,0) -> 0
B50: TOTAL | C50: =SUM(C45:C49) -> #REF! | D50: =SUM(D45:D49) -> #REF! | E50: =IFERROR(D50/C50,) -> 0 | F50: =IFERROR(G50/D50,0) -> 0 | G50: =SUM(G45:G49) -> #REF! | H50: =SUM(H45:H49) -> #REF! | I50: =IFERROR(H50/D50,0) -> 0 | J50: =IFERROR(G50/H50,0) -> 0
B51: ▶ 일자별 Total 성과
B52: 일자 | C52: 노출수 | D52: 클릭수 | E52: CTR | F52: CPC | G52: 광고비 | H52: 매출
H53: 전환수 | I53: CVR | J53: 전환당 비용
B54: 합계 | C54: =SUM(C55:C85) -> 0 | D54: =SUM(D55:D85) -> 0 | E54: =IFERROR(D54/C54,) -> 0 | F54: =IFERROR(G54/D54,0) -> 0 | G54: =SUM(G55:G85) -> 0 | H54: =SUM(H55:H85) -> 0 | I54: =IFERROR(H54/D54,0) -> 0 | J54: =IFERROR(G54/H54,0) -> 0
B55: 45778 | C55: =SUMIFS('카카오 RAW'!E:E,'카카오 RAW'!$A:$A,$B55,'카카오 RAW'!$D:$D,"프리미엄링크") -> 0 | D55: =SUMIFS('카카오 RAW'!F:F,'카카오 RAW'!$A:$A,$B55,'카카오 RAW'!$D:$D,"프리미엄링크") -> 0 | E55: =IFERROR(D55/C55,) -> 0 | F55: =IFERROR(G55/D55,0) -> 0 | G55: =SUMIFS('카카오 RAW'!H:H,'카카오 RAW'!$A:$A,$B55,'카카오 RAW'!$D:$D,"프리미엄링크") -> 0 | H55: =SUMIFS('카카오 RAW'!I:I,'카카오 RAW'!$A:$A,$B55,'카카오 RAW'!$D:$D,"프리미엄링크") -> 0 | I55: =IFERROR(H55/D55,0) -> 0 | J55: =IFERROR(G55/H55,0) -> 0
B56: 45779 | C56: =SUMIFS('카카오 RAW'!E:E,'카카오 RAW'!$A:$A,$B56,'카카오 RAW'!$D:$D,"프리미엄링크") -> 0 | D56: =SUMIFS('카카오 RAW'!F:F,'카카오 RAW'!$A:$A,$B56,'카카오 RAW'!$D:$D,"프리미엄링크") -> 0 | E56: =IFERROR(D56/C56,) -> 0 | F56: =IFERROR(G56/D56,0) -> 0 | G56: =SUMIFS('카카오 RAW'!H:H,'카카오 RAW'!$A:$A,$B56,'카카오 RAW'!$D:$D,"프리미엄링크") -> 0 | H56: =SUMIFS('카카오 RAW'!I:I,'카카오 RAW'!$A:$A,$B56,'카카오 RAW'!$D:$D,"프리미엄링크") -> 0 | I56: =IFERROR(H56/D56,0) -> 0 | J56: =IFERROR(G56/H56,0) -> 0
B57: 45780 | C57: =SUMIFS('카카오 RAW'!E:E,'카카오 RAW'!$A:$A,$B57,'카카오 RAW'!$D:$D,"프리미엄링크") -> 0 | D57: =SUMIFS('카카오 RAW'!F:F,'카카오 RAW'!$A:$A,$B57,'카카오 RAW'!$D:$D,"프리미엄링크") -> 0 | E57: =IFERROR(D57/C57,) -> 0 | F57: =IFERROR(G57/D57,0) -> 0 | G57: =SUMIFS('카카오 RAW'!H:H,'카카오 RAW'!$A:$A,$B57,'카카오 RAW'!$D:$D,"프리미엄링크") -> 0 | H57: =SUMIFS('카카오 RAW'!I:I,'카카오 RAW'!$A:$A,$B57,'카카오 RAW'!$D:$D,"프리미엄링크") -> 0 | I57: =IFERROR(H57/D57,0) -> 0 | J57: =IFERROR(G57/H57,0) -> 0
B58: 45781 | C58: =SUMIFS('카카오 RAW'!E:E,'카카오 RAW'!$A:$A,$B58,'카카오 RAW'!$D:$D,"프리미엄링크") -> 0 | D58: =SUMIFS('카카오 RAW'!F:F,'카카오 RAW'!$A:$A,$B58,'카카오 RAW'!$D:$D,"프리미엄링크") -> 0 | E58: =IFERROR(D58/C58,) -> 0 | F58: =IFERROR(G58/D58,0) -> 0 | G58: =SUMIFS('카카오 RAW'!H:H,'카카오 RAW'!$A:$A,$B58,'카카오 RAW'!$D:$D,"프리미엄링크") -> 0 | H58: =SUMIFS('카카오 RAW'!I:I,'카카오 RAW'!$A:$A,$B58,'카카오 RAW'!$D:$D,"프리미엄링크") -> 0 | I58: =IFERROR(H58/D58,0) -> 0 | J58: =IFERROR(G58/H58,0) -> 0
B59: 45782 | C59: =SUMIFS('카카오 RAW'!E:E,'카카오 RAW'!$A:$A,$B59,'카카오 RAW'!$D:$D,"프리미엄링크") -> 0 | D59: =SUMIFS('카카오 RAW'!F:F,'카카오 RAW'!$A:$A,$B59,'카카오 RAW'!$D:$D,"프리미엄링크") -> 0 | E59: =IFERROR(D59/C59,) -> 0 | F59: =IFERROR(G59/D59,0) -> 0 | G59: =SUMIFS('카카오 RAW'!H:H,'카카오 RAW'!$A:$A,$B59,'카카오 RAW'!$D:$D,"프리미엄링크") -> 0 | H59: =SUMIFS('카카오 RAW'!I:I,'카카오 RAW'!$A:$A,$B59,'카카오 RAW'!$D:$D,"프리미엄링크") -> 0 | I59: =IFERROR(H59/D59,0) -> 0 | J59: =IFERROR(G59/H59,0) -> 0
B60: 45783 | C60: =SUMIFS('카카오 RAW'!E:E,'카카오 RAW'!$A:$A,$B60,'카카오 RAW'!$D:$D,"프리미엄링크") -> 0 | D60: =SUMIFS('카카오 RAW'!F:F,'카카오 RAW'!$A:$A,$B60,'카카오 RAW'!$D:$D,"프리미엄링크") -> 0 | E60: =IFERROR(D60/C60,) -> 0 | F60: =IFERROR(G60/D60,0) -> 0 | G60: =SUMIFS('카카오 RAW'!H:H,'카카오 RAW'!$A:$A,$B60,'카카오 RAW'!$D:$D,"프리미엄링크") -> 0 | H60: =SUMIFS('카카오 RAW'!I:I,'카카오 RAW'!$A:$A,$B60,'카카오 RAW'!$D:$D,"프리미엄링크") -> 0 | I60: =IFERROR(H60/D60,0) -> 0 | J60: =IFERROR(G60/H60,0) -> 0
B61: 45784 | C61: =SUMIFS('카카오 RAW'!E:E,'카카오 RAW'!$A:$A,$B61,'카카오 RAW'!$D:$D,"프리미엄링크") -> 0 | D61: =SUMIFS('카카오 RAW'!F:F,'카카오 RAW'!$A:$A,$B61,'카카오 RAW'!$D:$D,"프리미엄링크") -> 0 | E61: =IFERROR(D61/C61,) -> 0 | F61: =IFERROR(G61/D61,0) -> 0 | G61: =SUMIFS('카카오 RAW'!H:H,'카카오 RAW'!$A:$A,$B61,'카카오 RAW'!$D:$D,"프리미엄링크") -> 0 | H61: =SUMIFS('카카오 RAW'!I:I,'카카오 RAW'!$A:$A,$B61,'카카오 RAW'!$D:$D,"프리미엄링크") -> 0 | I61: =IFERROR(H61/D61,0) -> 0 | J61: =IFERROR(G61/H61,0) -> 0
B62: 45785 | C62: =SUMIFS('카카오 RAW'!E:E,'카카오 RAW'!$A:$A,$B62,'카카오 RAW'!$D:$D,"프리미엄링크") -> 0 | D62: =SUMIFS('카카오 RAW'!F:F,'카카오 RAW'!$A:$A,$B62,'카카오 RAW'!$D:$D,"프리미엄링크") -> 0 | E62: =IFERROR(D62/C62,) -> 0 | F62: =IFERROR(G62/D62,0) -> 0 | G62: =SUMIFS('카카오 RAW'!H:H,'카카오 RAW'!$A:$A,$B62,'카카오 RAW'!$D:$D,"프리미엄링크") -> 0 | H62: =SUMIFS('카카오 RAW'!I:I,'카카오 RAW'!$A:$A,$B62,'카카오 RAW'!$D:$D,"프리미엄링크") -> 0 | I62: =IFERROR(H62/D62,0) -> 0 | J62: =IFERROR(G62/H62,0) -> 0
B63: 45786 | C63: =SUMIFS('카카오 RAW'!E:E,'카카오 RAW'!$A:$A,$B63,'카카오 RAW'!$D:$D,"프리미엄링크") -> 0 | D63: =SUMIFS('카카오 RAW'!F:F,'카카오 RAW'!$A:$A,$B63,'카카오 RAW'!$D:$D,"프리미엄링크") -> 0 | E63: =IFERROR(D63/C63,) -> 0 | F63: =IFERROR(G63/D63,0) -> 0 | G63: =SUMIFS('카카오 RAW'!H:H,'카카오 RAW'!$A:$A,$B63,'카카오 RAW'!$D:$D,"프리미엄링크") -> 0 | H63: =SUMIFS('카카오 RAW'!I:I,'카카오 RAW'!$A:$A,$B63,'카카오 RAW'!$D:$D,"프리미엄링크") -> 0 | I63: =IFERROR(H63/D63,0) -> 0 | J63: =IFERROR(G63/H63,0) -> 0
B64: 45787 | C64: =SUMIFS('카카오 RAW'!E:E,'카카오 RAW'!$A:$A,$B64,'카카오 RAW'!$D:$D,"프리미엄링크") -> 0 | D64: =SUMIFS('카카오 RAW'!F:F,'카카오 RAW'!$A:$A,$B64,'카카오 RAW'!$D:$D,"프리미엄링크") -> 0 | E64: =IFERROR(D64/C64,) -> 0 | F64: =IFERROR(G64/D64,0) -> 0 | G64: =SUMIFS('카카오 RAW'!H:H,'카카오 RAW'!$A:$A,$B64,'카카오 RAW'!$D:$D,"프리미엄링크") -> 0 | H64: =SUMIFS('카카오 RAW'!I:I,'카카오 RAW'!$A:$A,$B64,'카카오 RAW'!$D:$D,"프리미엄링크") -> 0 | I64: =IFERROR(H64/D64,0) -> 0 | J64: =IFERROR(G64/H64,0) -> 0
B65: 45788 | C65: =SUMIFS('카카오 RAW'!E:E,'카카오 RAW'!$A:$A,$B65,'카카오 RAW'!$D:$D,"프리미엄링크") -> 0 | D65: =SUMIFS('카카오 RAW'!F:F,'카카오 RAW'!$A:$A,$B65,'카카오 RAW'!$D:$D,"프리미엄링크") -> 0 | E65: =IFERROR(D65/C65,) -> 0 | F65: =IFERROR(G65/D65,0) -> 0 | G65: =SUMIFS('카카오 RAW'!H:H,'카카오 RAW'!$A:$A,$B65,'카카오 RAW'!$D:$D,"프리미엄링크") -> 0 | H65: =SUMIFS('카카오 RAW'!I:I,'카카오 RAW'!$A:$A,$B65,'카카오 RAW'!$D:$D,"프리미엄링크") -> 0 | I65: =IFERROR(H65/D65,0) -> 0 | J65: =IFERROR(G65/H65,0) -> 0
B66: 45789 | C66: =SUMIFS('카카오 RAW'!E:E,'카카오 RAW'!$A:$A,$B66,'카카오 RAW'!$D:$D,"프리미엄링크") -> 0 | D66: =SUMIFS('카카오 RAW'!F:F,'카카오 RAW'!$A:$A,$B66,'카카오 RAW'!$D:$D,"프리미엄링크") -> 0 | E66: =IFERROR(D66/C66,) -> 0 | F66: =IFERROR(G66/D66,0) -> 0 | G66: =SUMIFS('카카오 RAW'!H:H,'카카오 RAW'!$A:$A,$B66,'카카오 RAW'!$D:$D,"프리미엄링크") -> 0 | H66: =SUMIFS('카카오 RAW'!I:I,'카카오 RAW'!$A:$A,$B66,'카카오 RAW'!$D:$D,"프리미엄링크") -> 0 | I66: =IFERROR(H66/D66,0) -> 0 | J66: =IFERROR(G66/H66,0) -> 0
... B85: 45808 | C85: =SUMIFS('카카오 RAW'!E:E,'카카오 RAW'!$A:$A,$B85,'카카오 RAW'!$D:$D,"프리미엄링크") -> 0 | D85: =SUMIFS('카카오 RAW'!F:F,'카카오 RAW'!$A:$A,$B85,'카카오 RAW'!$D:$D,"프리미엄링크") -> 0 | E85: =IFERROR(D85/C85,) -> 0 | F85: =IFERROR(G85/D85,0) -> 0 | G85: =SUMIFS('카카오 RAW'!H:H,'카카오 RAW'!$A:$A,$B85,'카카오 RAW'!$D:$D,"프리미엄링크") -> 0 | H85: =SUMIFS('카카오 RAW'!I:I,'카카오 RAW'!$A:$A,$B85,'카카오 RAW'!$D:$D,"프리미엄링크") -> 0 | I85: =IFERROR(H85/D85,0) -> 0 | J85: =IFERROR(G85/H85,0) -> 0

Sheet 카카오_상세데이터
B2: 카카오 검색광고
B4: ▶ 기기 별 성과
B5: 캠페인 | D5: 노출수 | E5: 클릭수 | F5: CTR | G5: CPC | H5: 광고비 | I5: 매출
I6: 전환수 | J6: CVR | K6: 전환당 비용
B7: PC | D7: =SUMIFS('카카오 RAW'!E:E,'카카오 RAW'!$D:$D,"프리미엄링크",'카카오 RAW'!$B:$B,카카오_상세데이터!$B7) -> 36640 | E7: =SUMIFS('카카오 RAW'!F:F,'카카오 RAW'!$D:$D,"프리미엄링크",'카카오 RAW'!$B:$B,카카오_상세데이터!$B7) -> 147 | F7: =IFERROR(E7/D7,) -> 0.0040120087 | G7: =IFERROR(H7/E7,0) -> 77 | H7: =SUMIFS('카카오 RAW'!H:H,'카카오 RAW'!$D:$D,"프리미엄링크",'카카오 RAW'!$B:$B,카카오_상세데이터!$B7) -> 11319 | I7: =SUMIFS('카카오 RAW'!I:I,'카카오 RAW'!$D:$D,"프리미엄링크",'카카오 RAW'!$B:$B,카카오_상세데이터!$B7) -> 0 | J7: =IFERROR(I7/E7,0) -> 0 | K7: =IFERROR(H7/I7,0) -> 0
B8: 모바일 | D8: =SUMIFS('카카오 RAW'!E:E,'카카오 RAW'!$D:$D,"프리미엄링크",'카카오 RAW'!$B:$B,카카오_상세데이터!$B8) -> 132734 | E8: =SUMIFS('카카오 RAW'!F:F,'카카오 RAW'!$D:$D,"프리미엄링크",'카카오 RAW'!$B:$B,카카오_상세데이터!$B8) -> 479 | F8: =IFERROR(E8/D8,) -> 0.0036087212 | G8: =IFERROR(H8/E8,0) -> 77 | H8: =SUMIFS('카카오 RAW'!H:H,'카카오 RAW'!$D:$D,"프리미엄링크",'카카오 RAW'!$B:$B,카카오_상세데이터!$B8) -> 36883 | I8: =SUMIFS('카카오 RAW'!I:I,'카카오 RAW'!$D:$D,"프리미엄링크",'카카오 RAW'!$B:$B,카카오_상세데이터!$B8) -> 0 | J8: =IFERROR(I8/E8,0) -> 0 | K8: =IFERROR(H8/I8,0) -> 0
B9: TOTAL | D9: =SUM(D7:D8) -> 169374 | E9: =SUM(E7:E8) -> 626 | F9: =IFERROR(E9/D9,) -> 0.0036959628 | G9: =IFERROR(H9/E9,0) -> 77 | H9: =SUM(H7:H8) -> 48202 | I9: =SUM(I7:I8) -> 0 | J9: =IFERROR(I9/E9,0) -> 0 | K9: =IFERROR(H9/I9,0) -> 0
B11: ▶ 캠페인 별 성과
B12: 캠페인 | D12: 노출수 | E12: 클릭수 | F12: CTR | G12: CPC | H12: 광고비 | I12: 매출
I13: 전환수 | J13: CVR | K13: 전환당 비용
B14: 나라페이 메인 파워링크(검색지면) | D14: =SUMIFS('[1]카카오 RAW'!N:N,'[1]카카오 RAW'!$F:$F,"카카오",'[1]카카오 RAW'!$D:$D,카카오_상세데이터!$B14) -> #VALUE! | E14: =SUMIFS('[1]카카오 RAW'!O:O,'[1]카카오 RAW'!$F:$F,"카카오",'[1]카카오 RAW'!$D:$D,카카오_상세데이터!$B14) -> #VALUE! | F14: =IFERROR(E14/D14,) -> 0 | G14: =IFERROR(H14/E14,0) -> 0 | H14: =SUMIFS('[1]카카오 RAW'!P:P,'[1]카카오 RAW'!$F:$F,"카카오",'[1]카카오 RAW'!$D:$D,카카오_상세데이터!$B14) -> #VALUE! | I14: =SUMIFS('[1]파워링크 RAW'!Q:Q,'[1]파워링크 RAW'!$F:$F,"파워링크",'[1]파워링크 RAW'!$D:$D,카카오_상세데이터!$B14) -> #VALUE! | J14: =IFERROR(I14/E14,0) -> 0 | K14: =IFERROR(H14/I14,0) -> 0
B15: 나라페이 메인 파워링크(콘텐츠지면) | D15: =SUMIFS('[1]카카오 RAW'!N:N,'[1]카카오 RAW'!$F:$F,"카카오",'[1]카카오 RAW'!$D:$D,카카오_상세데이터!$B15) -> #VALUE! | E15: =SUMIFS('[1]카카오 RAW'!O:O,'[1]카카오 RAW'!$F:$F,"카카오",'[1]카카오 RAW'!$D:$D,카카오_상세데이터!$B15) -> #VALUE! | F15: =IFERROR(E15/D15,) -> 0 | G15: =IFERROR(H15/E15,0) -> 0 | H15: =SUMIFS('[1]카카오 RAW'!P:P,'[1]카카오 RAW'!$F:$F,"카카오",'[1]카카오 RAW'!$D:$D,카카오_상세데이터!$B15) -> #VALUE! | I15: =SUMIFS('[1]파워링크 RAW'!Q:Q,'[1]파워링크 RAW'!$F:$F,"파워링크",'[1]파워링크 RAW'!$D:$D,카카오_상세데이터!$B15) -> #VALUE! | J15: =IFERROR(I15/E15,0) -> 0 | K15: =IFERROR(H15/I15,0) -> 0
B16: 나라페이 서브 파워링크(검색지면) | D16: =SUMIFS('[1]카카오 RAW'!N:N,'[1]카카오 RAW'!$F:$F,"카카오",'[1]카카오 RAW'!$D:$D,카카오_상세데이터!$B16) -> #VALUE! | E16: =SUMIFS('[1]카카오 RAW'!O:O,'[1]카카오 RAW'!$F:$F,"카카오",'[1]카카오 RAW'!$D:$D,카카오_상세데이터!$B16) -> #VALUE! | F16: =IFERROR(E16/D16,) -> 0 | G16: =IFERROR(H16/E16,0) -> 0 | H16: =SUMIFS('[1]카카오 RAW'!P:P,'[1]카카오 RAW'!$F:$F,"카카오",'[1]카카오 RAW'!$D:$D,카카오_상세데이터!$B16) -> #VALUE! | I16: =SUMIFS('[1]파워링크 RAW'!Q:Q,'[1]파워링크 RAW'!$F:$F,"파워링크",'[1]파워링크 RAW'!$D:$D,카카오_상세데이터!$B16) -> #VALUE! | J16: =IFERROR(I16/E16,0) -> 0 | K16: =IFERROR(H16/I16,0) -> 0
B17: 나라페이 서브 파워링크(콘텐츠지면) | D17: =SUMIFS('[1]카카오 RAW'!N:N,'[1]카카오 RAW'!$F:$F,"카카오",'[1]카카오 RAW'!$D:$D,카카오_상세데이터!$B17) -> #VALUE! | E17: =SUMIFS('[1]카카오 RAW'!O:O,'[1]카카오 RAW'!$F:$F,"카카오",'[1]카카오 RAW'!$D:$D,카카오_상세데이터!$B17) -> #VALUE! | F17: =IFERROR(E17/D17,) -> 0 | G17: =IFERROR(H17/E17,0) -> 0 | H17: =SUMIFS('[1]카카오 RAW'!P:P,'[1]카카오 RAW'!$F:$F,"카카오",'[1]카카오 RAW'!$D:$D,카카오_상세데이터!$B17) -> #VALUE! | I17: =SUMIFS('[1]파워링크 RAW'!Q:Q,'[1]파워링크 RAW'!$F:$F,"파워링크",'[1]파워링크 RAW'!$D:$D,카카오_상세데이터!$B17) -> #VALUE! | J17: =IFERROR(I17/E17,0) -> 0 | K17: =IFERROR(H17/I17,0) -> 0
B18: 나라페이 파워컨텐츠 | D18: =SUMIFS('[1]카카오 RAW'!N:N,'[1]카카오 RAW'!$F:$F,"카카오",'[1]카카오 RAW'!$D:$D,카카오_상세데이터!$B18) -> #VALUE! | E18: =SUMIFS('[1]카카오 RAW'!O:O,'[1]카카오 RAW'!$F:$F,"카카오",'[1]카카오 RAW'!$D:$D,카카오_상세데이터!$B18) -> #VALUE! | F18: =IFERROR(E18/D18,) -> 0 | G18: =IFERROR(H18/E18,0) -> 0 | H18: =SUMIFS('[1]카카오 RAW'!P:P,'[1]카카오 RAW'!$F:$F,"카카오",'[1]카카오 RAW'!$D:$D,카카오_상세데이터!$B18) -> #VALUE! | I18: =SUMIFS('[1]파워링크 RAW'!Q:Q,'[1]파워링크 RAW'!$F:$F,"파워링크",'[1]파워링크 RAW'!$D:$D,카카오_상세데이터!$B18) -> #VALUE! | J18: =IFERROR(I18/E18,0) -> 0 | K18: =IFERROR(H18/I18,0) -> 0
B19: TOTAL | D19: =SUM(D14:D18) -> #VALUE! | E19: =SUM(E14:E18) -> #VALUE! | F19: =IFERROR(E19/D19,) -> 0 | G19: =IFERROR(H19/E19,0) -> 0 | H19: =SUM(H14:H18) -> #VALUE! | I19: =SUM(I14:I18) -> #VALUE! | J19: =IFERROR(I19/E19,0) -> 0 | K19: =IFERROR(H19/I19,0) -> 0
B21: ▶ 그룹 별 성과 | K21: * 광고비 내림차순
B22: 캠페인 | C22: 그룹 | D22: 노출수 | E22: 클릭수 | F22: CTR | G22: CPC | H22: 광고비 | I22: 매출
I23: 전환수 | J23: CVR | K23: 전환당 비용
B24: 페이파란 | C24: 단말기_콘텐츠 | D24: 169266 | E24: 626 | F24: =IFERROR(E24/D24,) -> 0.003698321 | G24: =IFERROR(H24/E24,0) -> 77 | H24: 48202 | I24: 0 | J24: =IFERROR(I24/E24,0) -> 0 | K24: =IFERROR(H24/I24,0) -> 0
B25: 페이파란 | C25: 단말기_검색 | D25: 108 | E25: 0 | F25: =IFERROR(E25/D25,) -> 0 | G25: =IFERROR(H25/E25,0) -> 0 | H25: 0 | I25: 0 | J25: =IFERROR(I25/E25,0) -> 0 | K25: =IFERROR(H25/I25,0) -> 0
E35: 0 | F35: =IFERROR(E35/D35,) -> 0 | G35: =IFERROR(H35/E35,0) -> 0 | H35: 0 | I35: 0 | J35: =IFERROR(I35/E35,0) -> 0 | K35: =IFERROR(H35/I35,0) -> 0
E36: 0 | F36: =IFERROR(E36/D36,) -> 0 | G36: =IFERROR(H36/E36,0) -> 0 | H36: 0 | I36: 0 | J36: =IFERROR(I36/E36,0) -> 0 | K36: =IFERROR(H36/I36,0) -> 0
E37: 0 | F37: =IFERROR(E37/D37,) -> 0 | G37: =IFERROR(H37/E37,0) -> 0 | H37: 0 | I37: 0 | J37: =IFERROR(I37/E37,0) -> 0 | K37: =IFERROR(H37/I37,0) -> 0
E38: 0 | F38: =IFERROR(E38/D38,) -> 0 | G38: =IFERROR(H38/E38,0) -> 0 | H38: 0 | I38: 0 | J38: =IFERROR(I38/E38,0) -> 0 | K38: =IFERROR(H38/I38,0) -> 0
E39: 0 | F39: =IFERROR(E39/D39,) -> 0 | G39: =IFERROR(H39/E39,0) -> 0 | H39: 0 | I39: 0 | J39: =IFERROR(I39/E39,0) -> 0 | K39: =IFERROR(H39/I39,0) -> 0
E40: 0 | F40: =IFERROR(E40/D40,) -> 0 | G40: =IFERROR(H40/E40,0) -> 0 | H40: 0 | I40: 0 | J40: =IFERROR(I40/E40,0) -> 0 | K40: =IFERROR(H40/I40,0) -> 0
F41: =IFERROR(E41/D41,) -> 0 | G41: =IFERROR(H41/E41,0) -> 0 | H41: 0 | I41: 0 | J41: =IFERROR(I41/E41,0) -> 0 | K41: =IFERROR(H41/I41,0) -> 0
F42: =IFERROR(E42/D42,) -> 0 | G42: =IFERROR(H42/E42,0) -> 0 | H42: 0 | I42: 0 | J42: =IFERROR(I42/E42,0) -> 0 | K42: =IFERROR(H42/I42,0) -> 0
F43: =IFERROR(E43/D43,) -> 0 | G43: =IFERROR(H43/E43,0) -> 0 | H43: 0 | I43: 0 | J43: =IFERROR(I43/E43,0) -> 0 | K43: =IFERROR(H43/I43,0) -> 0
H44: 0 | I44: 0
F45: =IFERROR(E45/D45,) -> 0 | G45: =IFERROR(H45/E45,0) -> 0 | H45: 0 | I45: 0 | J45: =IFERROR(I45/E45,0) -> 0 | K45: =IFERROR(H45/I45,0) -> 0
B46: TOTAL | D46: =SUM(D24:D45) -> 169374 | E46: =SUM(E24:E45) -> 626 | F46: =IFERROR(E46/D46,) -> 0.0036959628 | G46: =IFERROR(H46/E46,0) -> 77 | H46: =SUM(H24:H45) -> 48202 | I46: =SUM(I24:I45) -> 0 | J46: =IFERROR(I46/E46,0) -> 0 | K46: =IFERROR(H46/I46,0) -> 0

Sheet 카카오_PC키워드_주간
B2: 카카오_키워드별 주간 데이터 (PC)
C6: =파워링크_키워드_평일!C6 -> * 기간 : 2026.03.02~2026.03.06
C9: * (PC)
C10: 캠페인 | D10: 광고그룹 | E10: 키워드 | F10: 노출 | G10: 클릭 | H10: CTR | I10: CPC | J10: 광고비 | K10: 전환수 | L10: CVR | M10: 전환당 비용
C11: 합계 | D11: 합계 | E11: 총합 | F11: =SUM(F12:F1048576) -> 33 | G11: =SUM(G12:G1048576) -> 0 | H11: =G11/F11 -> 0 | I11: =IFERROR(J11/G11,0) -> 0 | J11: =SUM(J12:J1048576) -> 0 | K11: =SUM(K12:K1048576) -> 0 | L11: =IFERROR(K11/G11,0) -> 0 | M11: =IFERROR(K11/J11,0) -> 0
C12: 페이파란 | D12: 단말기_검색 | E12: 카드단말기 | F12: 24 | G12: 0 | H12: =IFERROR(G12/F12,0) -> 0 | I12: =IFERROR(J12/G12,0) -> 0 | J12: 0 | K12: 0 | L12: =IFERROR(K12/G12,0) -> 0 | M12: =IFERROR(K12/J12,0) -> 0
C13: 페이파란 | D13: 단말기_검색 | E13: 신용카드단말기 | F13: 5 | G13: 0 | H13: =IFERROR(G13/F13,0) -> 0 | I13: =IFERROR(J13/G13,0) -> 0 | J13: 0 | K13: 0 | L13: =IFERROR(K13/G13,0) -> 0 | M13: =IFERROR(K13/J13,0) -> 0
C14: 페이파란 | D14: 단말기_검색 | E14: 카드단말기구입 | F14: 3 | G14: 0 | H14: =IFERROR(G14/F14,0) -> 0 | I14: =IFERROR(J14/G14,0) -> 0 | J14: 0 | K14: 0 | L14: =IFERROR(K14/G14,0) -> 0 | M14: =IFERROR(K14/J14,0) -> 0
C15: 페이파란 | D15: 단말기_검색 | E15: 카드단말기임대 | F15: 1 | G15: 0 | H15: =IFERROR(G15/F15,0) -> 0 | I15: =IFERROR(J15/G15,0) -> 0 | J15: 0 | K15: 0 | L15: =IFERROR(K15/G15,0) -> 0 | M15: =IFERROR(K15/J15,0) -> 0

Sheet 카카오_MO키워드_주간
B2: 카카오_키워드별 주간 데이터 (MO)
C6: =카카오_PC키워드_주간!C6 -> * 기간 : 2026.03.02~2026.03.06
C9: * (MO)
C10: 캠페인 | D10: 광고그룹 | E10: 키워드 | F10: 노출 | G10: 클릭 | H10: CTR | I10: CPC | J10: 광고비 | K10: 전환수 | L10: CVR | M10: 전환당 비용
C11: 합계 | D11: 합계 | E11: 총합 | F11: =SUM(F12:F1048576) -> 12 | G11: =SUM(G12:G1048576) -> 0 | H11: =IFERROR(G11/F11,0) -> 0 | I11: =IFERROR(J11/G11,0) -> 0 | J11: =SUM(J12:J1048576) -> 0 | K11: =SUM(K12:K1048576) -> 0 | L11: =IFERROR(K11/G11,0) -> 0 | M11: =IFERROR(K11/J11,0) -> 0
C12: 페이파란 | D12: 단말기_검색 | E12: 카드단말기 | F12: 7 | G12: 0 | H12: 0 | I12: =IFERROR(J12/G12,0) -> 0 | J12: 0 | K12: 0 | L12: =IFERROR(K12/G12,0) -> 0 | M12: =IFERROR(K12/J12,0) -> 0
C13: 페이파란 | D13: 단말기_검색 | E13: 신용카드단말기 | F13: 3 | G13: 0 | H13: 0 | I13: =IFERROR(J13/G13,0) -> 0 | J13: 0 | K13: 0 | L13: =IFERROR(K13/G13,0) -> 0 | M13: =IFERROR(K13/J13,0) -> 0
C14: 페이파란 | D14: 단말기_검색 | E14: 카드단말기구입 | F14: 2 | G14: 0 | H14: 0 | I14: =IFERROR(J14/G14,0) -> 0 | J14: 0 | K14: 0 | L14: =IFERROR(K14/G14,0) -> 0 | M14: =IFERROR(K14/J14,0) -> 0

Sheet 카카오 RAW
A1: 일자 | B1: 기기 | C1: 캠페인 | D1: 매체 | E1: 노출 | F1: 클릭 | G1: 광고비 | H1: 광고비(*1.1) | I1: 구매수 | J1: 매출액
A2: 45748 | B2: 모바일 | C2: 페이파란 | D2: 프리미엄링크 | E2: 15259 | F2: 52 | G2: 3640 | H2: =G2*1.1 -> 4004 | I2: 0
A3: 45748 | B3: PC | C3: 페이파란 | D3: 프리미엄링크 | E3: 876 | F3: 0 | G3: 0 | H3: =G3*1.1 -> 0 | I3: 0
A4: 45749 | B4: 모바일 | C4: 페이파란 | D4: 프리미엄링크 | E4: 12302 | F4: 45 | G4: 3150 | H4: =G4*1.1 -> 3465 | I4: 0
A5: 45749 | B5: PC | C5: 페이파란 | D5: 프리미엄링크 | E5: 2664 | F5: 11 | G5: 770 | H5: =G5*1.1 -> 847 | I5: 0
A6: 45750 | B6: 모바일 | C6: 페이파란 | D6: 프리미엄링크 | E6: 10020 | F6: 31 | G6: 2170 | H6: =G6*1.1 -> 2387 | I6: 0
A7: 45750 | B7: PC | C7: 페이파란 | D7: 프리미엄링크 | E7: 2897 | F7: 21 | G7: 1470 | H7: =G7*1.1 -> 1617 | I7: 0
A8: 45751 | B8: 모바일 | C8: 페이파란 | D8: 프리미엄링크 | E8: 11465 | F8: 43 | G8: 3010 | H8: =G8*1.1 -> 3311 | I8: 0
A9: 45751 | B9: PC | C9: 페이파란 | D9: 프리미엄링크 | E9: 3207 | F9: 11 | G9: 770 | H9: =G9*1.1 -> 847 | I9: 0
A10: 45754 | B10: 모바일 | C10: 페이파란 | D10: 프리미엄링크 | E10: 4588 | F10: 12 | G10: 840 | H10: =G10*1.1 -> 924 | I10: 0
A11: 45754 | B11: PC | C11: 페이파란 | D11: 프리미엄링크 | E11: 8046 | F11: 41 | G11: 2870 | H11: =G11*1.1 -> 3157 | I11: 0
